Workbook

Sheet Instruction pour le projet
A2: TRAVAIL A FAIRE | G2: EVALUATION DU TRAVAIL
G3: critères | H3: Note
A4: Objectif du projet : Mettre en place un outil opérationnel permettant l’écoulement du bilan, le calcul automatisé des indicateurs de liquidité et de risque de taux, ainsi que la visualisation des analyses via un dashboard ergonomique et facilement exploitable. | G4: Compréhension du sujet | H4: 4
G5: Outil utilisé (VBA, python,…) | H5: 3
A6: plus precisement il faudrait : | G6: Design de l'interface | H6: 3
A7: 1- créer un interface utilisateur, qui permettra à l'ulisateur d'importer les inputs (les differents onglets du classeur), de faire le traitement de la donnée (les ecoulements et calcul des indicateurs) et de presenter les analyses (presenter l'analyse sur les différents indicateurs). Si possible permettre à l'utilisateur d'exporter les résultats (écoulements et analyses). | G7: Ehaustivité et Présentation des analyses | H7: 7
G8: Presenation du projet + redaction de la procedure d'utilisation de l'outil | H8: 3
A9: Les metriques à calculer sont : | G9: Total | H9: 20
A10: 1- analyse du bilan (analyse de la structure du bilan, analyse à priori de la liquidité et analyse à priori du financement)
A11: 2- le gap de liquidité statique
A12: 3 - le gap de liquidité dynamique
A13: 4 - le gap de liquidité statique stressé pour les differents scenarios de liquidité (idiosyncratique, systémique, combiné)
A14: 5 - le gap de liquidité dynamique stressé(idiosyncratique, systémique, combiné)
A15: 6 - le gap de taux fixé
A16: 7 - l'EVE à bilan statique
A17: 8 - sensibilité de l'EVE pour les differents scenarios de taux reglémentaire
A18: 9 - le SOT EVE et compoarer à 15% du Tier 1
A19: 10- la MNI à bilan constant (presenter la MNI du stock, la MNI de la nouvelle production et la MNI total)
A20: 11 - sensibilité de la MNI pour les différents scenarios de taux reglémentaire
A21: 12- le SOT MNI et comparer à 5% du tier 1
... A33: - les montant donnés sont en KEUR. Pour l'analyse il faudrait permet à l'utilisateur de les afficher en EUR (unité) ou KEUR (millier) ou MEUR (million) ou GEUR (milliard)

Sheet Bilan au 31_12_2025_BAUL
E1: E n liquidité | G1: E n taux | I1: 0 | J1: 1 | K1: 2 | L1: 3 | M1: 4 | N1: 5 | O1: 6 | P1: 7 | Q1: 8 | R1: 9 | S1: 10 | T1: 11 | U1: 12 | V1: 13 | W1: 14 | X1: 15 | Y1: 16 | Z1: 17 | AA1: 18 | AB1: 19 | AC1: 20 | AD1: 21 | AE1: 22 | AF1: 23 | AG1: 24 | AH1: 25 | AI1: 26 | AJ1: 27 | AK1: 28 | AL1: 29 | AM1: 30 | AN1: 31 | AO1: 32 | AP1: 33 | AQ1: 34 | AR1: 35 | AS1: 36 | AT1: 37 | AU1: 38 | AV1: 39 | AW1: 40 | AX1: 41 | AY1: 42 | AZ1: 43 | BA1: 44 | BB1: 45 | BC1: 46 | BD1: 47 | BE1: 48 | BF1: 49 | BG1: 50 | BH1: 51 | BI1: 52 | BJ1: 53 | BK1: 54 | BL1: 55 | BM1: 56 | BN1: 57 | BO1: 58 | BP1: 59 | BQ1: 60 | BR1: 61 | BS1: 62 | BT1: 63 | BU1: 64 | BV1: 65 | BW1: 66 | BX1: 67 | BY1: 68 | BZ1: 69 | CA1: 70 | CB1: 71 | CC1: 72 | CD1: 73 | CE1: 74 | CF1: 75 | CG1: 76 | CH1: 77 | CI1: 78 | CJ1: 79 | CK1: 80 | CL1: 81 | CM1: 82 | CN1: 83 | CO1: 84 | CP1: 85 | CQ1: 86 | CR1: 87 | CS1: 88 | CT1: 89 | CU1: 90 | CV1: 91 | CW1: 92 | CX1: 93 | CY1: 94 | CZ1: 95 | DA1: 96 | DB1: 97 | DC1: 98 | DD1: 99 | DE1: 100 | DF1: 101 | DG1: 102 | DH1: 103 | DI1: 104 | DJ1: 105 | DK1: 106 | DL1: 107 | DM1: 108 | DN1: 109 | DO1: 110 | DP1: 111 | DQ1: 112 | DR1: 113 | DS1: 114 | DT1: 115 | DU1: 116 | DV1: 117 | DW1: 118 | DX1: 119 | DY1: 120
A2: Date d’arrêté | B2: Bilan | C2: Poste du bilan | D2: Taux d'intérèt moyen | E2: Loi d'écoulement | F2: Durée moyenne (en mois) | G2: Loi d'écoulement | H2: Durée moyenne (en mois) | I2: Montant (en k€) | J2: M1 | K2: M2 | L2: M3 | M2: M4 | N2: M5 | O2: M6 | P2: M7 | Q2: M8 | R2: M9 | S2: M10 | T2: M11 | U2: M12 | V2: M13 | W2: M14 | X2: M15 | Y2: M16 | Z2: M17 | AA2: M18 | AB2: M19 | AC2: M20 | AD2: M21 | AE2: M22 | AF2: M23 | AG2: M24 | AH2: M25 | AI2: M26 | AJ2: M27 | AK2: M28 | AL2: M29 | AM2: M30 | AN2: M31 | AO2: M32 | AP2: M33 | AQ2: M34 | AR2: M35 | AS2: M36 | AT2: M37 | AU2: M38 | AV2: M39 | AW2: M40 | AX2: M41 | AY2: M42 | AZ2: M43 | BA2: M44 | BB2: M45 | BC2: M46 | BD2: M47 | BE2: M48 | BF2: M49 | BG2: M50 | BH2: M51 | BI2: M52 | BJ2: M53 | BK2: M54 | BL2: M55 | BM2: M56 | BN2: M57 | BO2: M58 | BP2: M59 | BQ2: M60 | BR2: M61 | BS2: M62 | BT2: M63 | BU2: M64 | BV2: M65 | BW2: M66 | BX2: M67 | BY2: M68 | BZ2: M69 | CA2: M70 | CB2: M71 | CC2: M72 | CD2: M73 | CE2: M74 | CF2: M75 | CG2: M76 | CH2: M77 | CI2: M78 | CJ2: M79 | CK2: M80 | CL2: M81 | CM2: M82 | CN2: M83 | CO2: M84 | CP2: M85 | CQ2: M86 | CR2: M87 | CS2: M88 | CT2: M89 | CU2: M90 | CV2: M91 | CW2: M92 | CX2: M93 | CY2: M94 | CZ2: M95 | DA2: M96 | DB2: M97 | DC2: M98 | DD2: M99 | DE2: M100 | DF2: M101 | DG2: M102 | DH2: M103 | DI2: M104 | DJ2: M105 | DK2: M106 | DL2: M107 | DM2: M108 | DN2: M109 | DO2: M110 | DP2: M111 | DQ2: M112 | DR2: M113 | DS2: M114 | DT2: M115 | DU2: M116 | DV2: M117 | DW2: M118 | DX2: M119 | DY2: M120
A3: 46022 | B3: ACTIF | C3: CAISSE, BANQUES CENTRALES | I3: 1255.124 | J3: =SUM(J4:J5) -> 1244.3264 | K3: =SUM(K4:K5) -> 1233.5288 | L3: =SUM(L4:L5) -> 1222.7312 | M3: =SUM(M4:M5) -> 1211.9336 | N3: =SUM(N4:N5) -> 1201.136 | O3: =SUM(O4:O5) -> 1190.3384 | P3: =SUM(P4:P5) -> 1179.5408 | Q3: =SUM(Q4:Q5) -> 1168.7433 | ... DY3: =SUM(DY4:DY5) -> 0
A4: 46022 | B4: ACTIF | C4: - Caisse | D4: 0 | E4: Linéaire | F4: 60 | G4: In fine | H4: 60 | I4: 40.58686 | J4: =IF(J$1<$F4,$I4*(($F4-J$1)/$F4),0) -> 39.910412 | K4: =IF(K$1<$F4,$I4*(($F4-K$1)/$F4),0) -> 39.233965 | L4: =IF(L$1<$F4,$I4*(($F4-L$1)/$F4),0) -> 38.557517 | M4: =IF(M$1<$F4,$I4*(($F4-M$1)/$F4),0) -> 37.881069 | N4: =IF(N$1<$F4,$I4*(($F4-N$1)/$F4),0) -> 37.204622 | O4: =IF(O$1<$F4,$I4*(($F4-O$1)/$F4),0) -> 36.528174 | P4: =IF(P$1<$F4,$I4*(($F4-P$1)/$F4),0) -> 35.851726 | Q4: =IF(Q$1<$F4,$I4*(($F4-Q$1)/$F4),0) -> 35.175279 | ... DY4: =IF(DY$1<$F4,$I4*(($F4-DY$1)/$F4),0) -> 0
A5: 46022 | B5: ACTIF | C5: - Compte courant BDF | D5: 0.00040572687 | E5: Linéaire | F5: 120 | G5: Ine fine | H5: 120 | I5: 1214.5371 | J5: =IF(J$1<$F5,$I5*(($F5-J$1)/$F5),0) -> 1204.416 | K5: =IF(K$1<$F5,$I5*(($F5-K$1)/$F5),0) -> 1194.2948 | L5: =IF(L$1<$F5,$I5*(($F5-L$1)/$F5),0) -> 1184.1737 | M5: =IF(M$1<$F5,$I5*(($F5-M$1)/$F5),0) -> 1174.0525 | N5: =IF(N$1<$F5,$I5*(($F5-N$1)/$F5),0) -> 1163.9314 | O5: =IF(O$1<$F5,$I5*(($F5-O$1)/$F5),0) -> 1153.8103 | P5: =IF(P$1<$F5,$I5*(($F5-P$1)/$F5),0) -> 1143.6891 | Q5: =IF(Q$1<$F5,$I5*(($F5-Q$1)/$F5),0) -> 1133.568 | ... DY5: =IF(DY$1<$F5,$I5*(($F5-DY$1)/$F5),0) -> 0
A6: 46022 | B6: ACTIF | C6: CREANCES SUR LES ETS DE CREDIT | I6: 28006.945 | J6: =SUM(J7:J8) -> 24825.899 | K6: =SUM(K7:K8) -> 21644.854 | L6: =SUM(L7:L8) -> 18463.808 | M6: =SUM(M7:M8) -> 15282.762 | N6: =SUM(N7:N8) -> 12101.717 | O6: =SUM(O7:O8) -> 8920.671 | P6: =SUM(P7:P8) -> 8920.671 | Q6: =SUM(Q7:Q8) -> 8920.671 | ... DY6: =SUM(DY7:DY8) -> 0
A7: 46022 | B7: ACTIF | C7: - A vue | D7: 0 | E7: Linéaire | F7: 6 | G7: Linéaire | H7: 6 | I7: 19086.274 | J7: =IF(J$1<$F7,$I7*(($F7-J$1)/$F7),0) -> 15905.228 | K7: =IF(K$1<$F7,$I7*(($F7-K$1)/$F7),0) -> 12724.183 | L7: =IF(L$1<$F7,$I7*(($F7-L$1)/$F7),0) -> 9543.137 | M7: =IF(M$1<$F7,$I7*(($F7-M$1)/$F7),0) -> 6362.0913 | N7: =IF(N$1<$F7,$I7*(($F7-N$1)/$F7),0) -> 3181.0457 | O7: =IF(O$1<$F7,$I7*(($F7-O$1)/$F7),0) -> 0 | P7: =IF(P$1<$F7,$I7*(($F7-P$1)/$F7),0) -> 0 | Q7: =IF(Q$1<$F7,$I7*(($F7-Q$1)/$F7),0) -> 0 | ... DY7: =IF(DY$1<$F7,$I7*(($F7-DY$1)/$F7),0) -> 0
A8: 46022 | B8: ACTIF | C8: - A terme | D8: 0.02489751 | E8: In fine | F8: 12 | G8: In fine | H8: 12 | I8: 8920.671 | J8: =IF(J$1<$F8,$I8,0) -> 8920.671 | K8: =IF(K$1<$F8,$I8,0) -> 8920.671 | L8: =IF(L$1<$F8,$I8,0) -> 8920.671 | M8: =IF(M$1<$F8,$I8,0) -> 8920.671 | N8: =IF(N$1<$F8,$I8,0) -> 8920.671 | O8: =IF(O$1<$F8,$I8,0) -> 8920.671 | P8: =IF(P$1<$F8,$I8,0) -> 8920.671 | Q8: =IF(Q$1<$F8,$I8,0) -> 8920.671 | ... DY8: =IF(DY$1<$F8,$I8,0) -> 0
A9: 46022 | B9: ACTIF | C9: CREANCES SUR LA CLIENTELE | I9: 125650.32 | J9: =SUM(J10:J12) -> 45066.509 | K9: =SUM(K10:K12) -> 40146.149 | L9: =SUM(L10:L12) -> 35212.566 | M9: =SUM(M10:M12) -> 30265.727 | N9: =SUM(N10:N12) -> 25305.594 | O9: =SUM(O10:O12) -> 20332.132 | P9: =SUM(P10:P12) -> 15345.305 | Q9: =SUM(Q10:Q12) -> 10345.078 | ... DY9: =SUM(DY10:DY12) -> 0
A10: 46022 | B10: ACTIF | C10: - Créances commerciales | D10: 0.048443032 | E10: Constant | F10: 60 | G10: Constant | H10: 60 | I10: 358.117 | J10: =IF(J$1<$F10,(I10*(1+($D10/12)))-(-PMT($D10/12,$F10,$I10)),0) -> 352.8301 | K10: =IF(K$1<$F10,(J10*(1+($D10/12)))-(-PMT($D10/12,$F10,$I10)),0) -> 347.52185 | L10: =IF(L$1<$F10,(K10*(1+($D10/12)))-(-PMT($D10/12,$F10,$I10)),0) -> 342.19217 | M10: =IF(M$1<$F10,(L10*(1+($D10/12)))-(-PMT($D10/12,$F10,$I10)),0) -> 336.84098 | N10: =IF(N$1<$F10,(M10*(1+($D10/12)))-(-PMT($D10/12,$F10,$I10)),0) -> 331.46818 | O10: =IF(O$1<$F10,(N10*(1+($D10/12)))-(-PMT($D10/12,$F10,$I10)),0) -> 326.0737 | P10: =IF(P$1<$F10,(O10*(1+($D10/12)))-(-PMT($D10/12,$F10,$I10)),0) -> 320.65744 | Q10: =IF(Q$1<$F10,(P10*(1+($D10/12)))-(-PMT($D10/12,$F10,$I10)),0) -> 315.21931 | ... DY10: =IF(DY$1<$F10,(DX10*(1+($D10/12)))-(-PMT($D10/12,$F10,$I10)),0) -> 0
A11: 46022 | B11: ACTIF | C11: - Autres concours à la clientèle | D11: 0.032228873 | E11: Constant | F11: 10 | G11: Constant | H11: 10 | I11: 49615.566 | J11: =IF(J$1<$F11,(I11*(1+($D11/12)))-(-PMT($D11/12,$F11,$I11)),0) -> 44713.679 | K11: =IF(K$1<$F11,(J11*(1+($D11/12)))-(-PMT($D11/12,$F11,$I11)),0) -> 39798.627 | L11: =IF(L$1<$F11,(K11*(1+($D11/12)))-(-PMT($D11/12,$F11,$I11)),0) -> 34870.374 | M11: =IF(M$1<$F11,(L11*(1+($D11/12)))-(-PMT($D11/12,$F11,$I11)),0) -> 29928.886 | N11: =IF(N$1<$F11,(M11*(1+($D11/12)))-(-PMT($D11/12,$F11,$I11)),0) -> 24974.125 | O11: =IF(O$1<$F11,(N11*(1+($D11/12)))-(-PMT($D11/12,$F11,$I11)),0) -> 20006.058 | P11: =IF(P$1<$F11,(O11*(1+($D11/12)))-(-PMT($D11/12,$F11,$I11)),0) -> 15024.648 | Q11: =IF(Q$1<$F11,(P11*(1+($D11/12)))-(-PMT($D11/12,$F11,$I11)),0) -> 10029.858 | ... DY11: =IF(DY$1<$F11,(DX11*(1+($D11/12)))-(-PMT($D11/12,$F11,$I11)),0) -> 0
A12: 46022 | B12: ACTIF | C12: - Comptes ordinaires débiteurs | D12: 0.039912213 | E12: In fine | F12: 1 | G12: In fine | H12: 1 | I12: 75676.636 | J12: =IF(J$1<$F12,$I12,0) -> 0 | K12: =IF(K$1<$F12,$I12,0) -> 0 | L12: =IF(L$1<$F12,$I12,0) -> 0 | M12: =IF(M$1<$F12,$I12,0) -> 0 | N12: =IF(N$1<$F12,$I12,0) -> 0 | O12: =IF(O$1<$F12,$I12,0) -> 0 | P12: =IF(P$1<$F12,$I12,0) -> 0 | Q12: =IF(Q$1<$F12,$I12,0) -> 0 | ... DY12: =IF(DY$1<$F12,$I12,0) -> 0
A13: 46022 | B13: ACTIF | C13: Investissements financiers | D13: 0.05 | E13: Ine fine | F13: 84 | G13: Ine fine | H13: 84 | I13: 28 | J13: =IF(J$1<$F13,$I13,0) -> 28 | K13: =IF(K$1<$F13,$I13,0) -> 28 | L13: =IF(L$1<$F13,$I13,0) -> 28 | M13: =IF(M$1<$F13,$I13,0) -> 28 | N13: =IF(N$1<$F13,$I13,0) -> 28 | O13: =IF(O$1<$F13,$I13,0) -> 28 | P13: =IF(P$1<$F13,$I13,0) -> 28 | Q13: =IF(Q$1<$F13,$I13,0) -> 28 | ... DY13: =IF(DY$1<$F13,$I13,0) -> 0
A14: 46022 | B14: ACTIF | C14: Immobilisations corporelles et incorporelles | E14: Linéaire | F14: 120 | G14: Linéaire | H14: 120 | I14: 82 | J14: =IF(J$1<$F14,$I14*(($F14-J$1)/$F14),0) -> 81.316667 | K14: =IF(K$1<$F14,$I14*(($F14-K$1)/$F14),0) -> 80.633333 | L14: =IF(L$1<$F14,$I14*(($F14-L$1)/$F14),0) -> 79.95 | M14: =IF(M$1<$F14,$I14*(($F14-M$1)/$F14),0) -> 79.266667 | N14: =IF(N$1<$F14,$I14*(($F14-N$1)/$F14),0) -> 78.583333 | O14: =IF(O$1<$F14,$I14*(($F14-O$1)/$F14),0) -> 77.9 | P14: =IF(P$1<$F14,$I14*(($F14-P$1)/$F14),0) -> 77.216667 | Q14: =IF(Q$1<$F14,$I14*(($F14-Q$1)/$F14),0) -> 76.533333 | ... DY14: =IF(DY$1<$F14,$I14*(($F14-DY$1)/$F14),0) -> 0
A15: 46022 | B15: ACTIF | C15: Autres actifs | E15: Linéaire | F15: 120 | G15: Linéaire | H15: 120 | I15: 570 | J15: =IF(J$1<$F15,$I15*(($F15-J$1)/$F15),0) -> 565.25 | K15: =IF(K$1<$F15,$I15*(($F15-K$1)/$F15),0) -> 560.5 | L15: =IF(L$1<$F15,$I15*(($F15-L$1)/$F15),0) -> 555.75 | M15: =IF(M$1<$F15,$I15*(($F15-M$1)/$F15),0) -> 551 | N15: =IF(N$1<$F15,$I15*(($F15-N$1)/$F15),0) -> 546.25 | O15: =IF(O$1<$F15,$I15*(($F15-O$1)/$F15),0) -> 541.5 | P15: =IF(P$1<$F15,$I15*(($F15-P$1)/$F15),0) -> 536.75 | Q15: =IF(Q$1<$F15,$I15*(($F15-Q$1)/$F15),0) -> 532 | ... DY15: =IF(DY$1<$F15,$I15*(($F15-DY$1)/$F15),0) -> 0
A16: 46022 | B16: ACTIF | C16: Total actif | I16: =I3+I6+I9+I13+I14+I15 -> 155592.39 | J16: =J3+J6+J9+SUM(J13:J15) -> 71811.302 | K16: =K3+K6+K9+SUM(K13:K15) -> 63693.665 | L16: =L3+L6+L9+SUM(L13:L15) -> 55562.806 | M16: =M3+M6+M9+SUM(M13:M15) -> 47418.689 | N16: =N3+N6+N9+SUM(N13:N15) -> 39261.28 | O16: =O3+O6+O9+SUM(O13:O15) -> 31090.541 | P16: =P3+P6+P9+SUM(P13:P15) -> 26087.483 | Q16: =Q3+Q6+Q9+SUM(Q13:Q15) -> 21071.025 | ... DY16: =DY3+DY6+DY9+SUM(DY13:DY15) -> 0
A17: 46022 | B17: PASSIF | C17: DETTES ENVERS ETS DE CREDIT | I17: =I18+I19 -> 74095.3 | J17: =SUM(J18:J19) -> 73528.24 | K17: =SUM(K18:K19) -> 73150.2 | L17: =SUM(L18:L19) -> 72772.16 | M17: =SUM(M18:M19) -> 72394.12 | N17: =SUM(N18:N19) -> 72205.1 | O17: =SUM(O18:O19) -> 72205.1 | P17: =SUM(P18:P19) -> 72205.1 | Q17: =SUM(Q18:Q19) -> 72205.1 | ... DY17: =SUM(DY18:DY19) -> 0
A18: 46022 | B18: PASSIF | C18: - A vue | D18: 0 | E18: 90%-20%*t, t<=4mois | F18: 4 | G18: In fine | H18: 4 | I18: 1890.2 | J18: =IF(J$1<=$F18,$I18*(90%-(20%*J$1)),0) -> 1323.14 | K18: =IF(K$1<=$F18,$I18*(90%-(20%*K$1)),0) -> 945.1 | L18: =IF(L$1<=$F18,$I18*(90%-(20%*L$1)),0) -> 567.06 | M18: =IF(M$1<=$F18,$I18*(90%-(20%*M$1)),0) -> 189.02 | N18: =IF(N$1<=$F18,$I18*(90%-(20%*N$1)),0) -> 0 | O18: =IF(O$1<=$F18,$I18*(90%-(20%*O$1)),0) -> 0 | P18: =IF(P$1<=$F18,$I18*(90%-(20%*P$1)),0) -> 0 | Q18: =IF(Q$1<=$F18,$I18*(90%-(20%*Q$1)),0) -> 0 | ... DY18: =IF(DY$1<=$F18,$I18*(90%-(20%*DY$1)),0) -> 0
A19: 46022 | B19: PASSIF | C19: - A terme | D19: 0.0138965 | E19: Ine fine | F19: 24 | G19: Ine fine | H19: 24 | I19: 72205.1 | J19: =IF(J$1<$F19,$I19,0) -> 72205.1 | K19: =IF(K$1<$F19,$I19,0) -> 72205.1 | L19: =IF(L$1<$F19,$I19,0) -> 72205.1 | M19: =IF(M$1<$F19,$I19,0) -> 72205.1 | N19: =IF(N$1<$F19,$I19,0) -> 72205.1 | O19: =IF(O$1<$F19,$I19,0) -> 72205.1 | P19: =IF(P$1<$F19,$I19,0) -> 72205.1 | Q19: =IF(Q$1<$F19,$I19,0) -> 72205.1 | ... DY19: =IF(DY$1<$F19,$I19,0) -> 0
A20: 46022 | B20: PASSIF | C20: CPTES CREDITEURS DE LA CLIENTELE | I20: 50161.059 | J20: =SUM(J21:J22) -> 43848.513 | K20: =SUM(K21:K22) -> 40644.299 | L20: =SUM(L21:L22) -> 38020.91 | M20: =SUM(M21:M22) -> 35873.06 | N20: =SUM(N21:N22) -> 34114.55 | O20: =SUM(O21:O22) -> 32674.804 | P20: =SUM(P21:P22) -> 31496.039 | Q20: =SUM(Q21:Q22) -> 30530.948 | ... DY20: =SUM(DY21:DY22) -> 8.1505852e-07
A21: 46022 | B21: PASSIF | C21: - A vue | D21: 0 | E21: 90%*exp(-20%*t), t<=120 mois | F21: 120 | G21: Linéaire | H21: 120 | I21: 23989.094 | J21: =IF(J$1<=$F21,$I21*(90%*EXP(-20%*J$1)),0) -> 17676.548 | K21: =IF(K$1<=$F21,$I21*(90%*EXP(-20%*K$1)),0) -> 14472.334 | L21: =IF(L$1<=$F21,$I21*(90%*EXP(-20%*L$1)),0) -> 11848.945 | M21: =IF(M$1<=$F21,$I21*(90%*EXP(-20%*M$1)),0) -> 9701.0953 | N21: =IF(N$1<=$F21,$I21*(90%*EXP(-20%*N$1)),0) -> 7942.585 | O21: =IF(O$1<=$F21,$I21*(90%*EXP(-20%*O$1)),0) -> 6502.8386 | P21: =IF(P$1<=$F21,$I21*(90%*EXP(-20%*P$1)),0) -> 5324.074 | Q21: =IF(Q$1<=$F21,$I21*(90%*EXP(-20%*Q$1)),0) -> 4358.9831 | ... DY21: =IF(DY$1<=$F21,$I21*(90%*EXP(-20%*DY$1)),0) -> 8.1505852e-07
A22: 46022 | B22: PASSIF | C22: - A terme | D22: 0.0083386457 | E22: In fine | F22: 60 | G22: In fine | H22: 60 | I22: 26171.965 | J22: =IF(J$1<$F22,$I22,0) -> 26171.965 | K22: =IF(K$1<$F22,$I22,0) -> 26171.965 | L22: =IF(L$1<$F22,$I22,0) -> 26171.965 | M22: =IF(M$1<$F22,$I22,0) -> 26171.965 | N22: =IF(N$1<$F22,$I22,0) -> 26171.965 | O22: =IF(O$1<$F22,$I22,0) -> 26171.965 | P22: =IF(P$1<$F22,$I22,0) -> 26171.965 | Q22: =IF(Q$1<$F22,$I22,0) -> 26171.965 | ... DY22: =IF(DY$1<$F22,$I22,0) -> 0
A23: 46022 | B23: PASSIF | C23: Autres passifs | D23: 0 | E23: Linéaire | F23: 120 | G23: Linéaire | H23: 120 | I23: 2297.337 | J23: =IF(J$1<$F23,$I23*(($F23-J$1)/$F23),0) -> 2278.1925 | K23: =IF(K$1<$F23,$I23*(($F23-K$1)/$F23),0) -> 2259.048 | L23: =IF(L$1<$F23,$I23*(($F23-L$1)/$F23),0) -> 2239.9036 | M23: =IF(M$1<$F23,$I23*(($F23-M$1)/$F23),0) -> 2220.7591 | N23: =IF(N$1<$F23,$I23*(($F23-N$1)/$F23),0) -> 2201.6146 | O23: =IF(O$1<$F23,$I23*(($F23-O$1)/$F23),0) -> 2182.4702 | P23: =IF(P$1<$F23,$I23*(($F23-P$1)/$F23),0) -> 2163.3257 | Q23: =IF(Q$1<$F23,$I23*(($F23-Q$1)/$F23),0) -> 2144.1812 | ... DY23: =IF(DY$1<$F23,$I23*(($F23-DY$1)/$F23),0) -> 0
A24: 46022 | B24: PASSIF | C24: Provisions pour risques et charges | D24: 0 | E24: Linéaire | F24: 120 | G24: Linéaire | H24: 120 | I24: 2994.787 | J24: =IF(J$1<$F24,$I24*(($F24-J$1)/$F24),0) -> 2969.8304 | K24: =IF(K$1<$F24,$I24*(($F24-K$1)/$F24),0) -> 2944.8739 | L24: =IF(L$1<$F24,$I24*(($F24-L$1)/$F24),0) -> 2919.9173 | M24: =IF(M$1<$F24,$I24*(($F24-M$1)/$F24),0) -> 2894.9608 | N24: =IF(N$1<$F24,$I24*(($F24-N$1)/$F24),0) -> 2870.0042 | O24: =IF(O$1<$F24,$I24*(($F24-O$1)/$F24),0) -> 2845.0476 | P24: =IF(P$1<$F24,$I24*(($F24-P$1)/$F24),0) -> 2820.0911 | Q24: =IF(Q$1<$F24,$I24*(($F24-Q$1)/$F24),0) -> 2795.1345 | ... DY24: =IF(DY$1<$F24,$I24*(($F24-DY$1)/$F24),0) -> 0
A25: 46022 | B25: PASSIF | C25: Financement LT | D25: 0.035 | E25: In fine | F25: 72 | G25: In fine | H25: 72 | I25: 130 | J25: =IF(J$1<$F25,$I25,0) -> 130 | K25: =IF(K$1<$F25,$I25,0) -> 130 | L25: =IF(L$1<$F25,$I25,0) -> 130 | M25: =IF(M$1<$F25,$I25,0) -> 130 | N25: =IF(N$1<$F25,$I25,0) -> 130 | O25: =IF(O$1<$F25,$I25,0) -> 130 | P25: =IF(P$1<$F25,$I25,0) -> 130 | Q25: =IF(Q$1<$F25,$I25,0) -> 130 | ... DY25: =IF(DY$1<$F25,$I25,0) -> 0
A26: 46022 | B26: PASSIF | C26: Capitaux propres | I26: 25913.849 | J26: =SUM(J27:J33) -> 25697.9 | K26: =SUM(K27:K33) -> 25481.952 | L26: =SUM(L27:L33) -> 25266.003 | M26: =SUM(M27:M33) -> 25050.054 | N26: =SUM(N27:N33) -> 24834.105 | O26: =SUM(O27:O33) -> 24618.157 | P26: =SUM(P27:P33) -> 24402.208 | Q26: =SUM(Q27:Q33) -> 24186.259 | ... DY26: =SUM(DY27:DY33) -> 0
A27: 46022 | B27: PASSIF | C27: FRBG | D27: 0 | E27: Linéaire | F27: 120 | G27: Linéaire | H27: 120 | I27: 476.541 | J27: =IF(J$1<$F27,$I27*(($F27-J$1)/$F27),0) -> 472.56983 | K27: =IF(K$1<$F27,$I27*(($F27-K$1)/$F27),0) -> 468.59865 | L27: =IF(L$1<$F27,$I27*(($F27-L$1)/$F27),0) -> 464.62748 | M27: =IF(M$1<$F27,$I27*(($F27-M$1)/$F27),0) -> 460.6563 | N27: =IF(N$1<$F27,$I27*(($F27-N$1)/$F27),0) -> 456.68513 | O27: =IF(O$1<$F27,$I27*(($F27-O$1)/$F27),0) -> 452.71395 | P27: =IF(P$1<$F27,$I27*(($F27-P$1)/$F27),0) -> 448.74277 | Q27: =IF(Q$1<$F27,$I27*(($F27-Q$1)/$F27),0) -> 444.7716 | ... DY27: =IF(DY$1<$F27,$I27*(($F27-DY$1)/$F27),0) -> 0
A28: 46022 | B28: PASSIF | C28: Capital souscrit | D28: 0 | E28: Linéaire | F28: 120 | G28: Linéaire | H28: 120 | I28: 18000.179 | J28: =IF(J$1<$F28,$I28*(($F28-J$1)/$F28),0) -> 17850.178 | K28: =IF(K$1<$F28,$I28*(($F28-K$1)/$F28),0) -> 17700.176 | L28: =IF(L$1<$F28,$I28*(($F28-L$1)/$F28),0) -> 17550.175 | M28: =IF(M$1<$F28,$I28*(($F28-M$1)/$F28),0) -> 17400.173 | N28: =IF(N$1<$F28,$I28*(($F28-N$1)/$F28),0) -> 17250.172 | O28: =IF(O$1<$F28,$I28*(($F28-O$1)/$F28),0) -> 17100.17 | P28: =IF(P$1<$F28,$I28*(($F28-P$1)/$F28),0) -> 16950.169 | Q28: =IF(Q$1<$F28,$I28*(($F28-Q$1)/$F28),0) -> 16800.167 | ... DY28: =IF(DY$1<$F28,$I28*(($F28-DY$1)/$F28),0) -> 0
A29: 46022 | B29: PASSIF | C29: Prime d'émission | D29: 0 | E29: Linéaire | F29: 120 | G29: Linéaire | H29: 120 | I29: 2.22 | J29: =IF(J$1<$F29,$I29*(($F29-J$1)/$F29),0) -> 2.2015 | K29: =IF(K$1<$F29,$I29*(($F29-K$1)/$F29),0) -> 2.183 | L29: =IF(L$1<$F29,$I29*(($F29-L$1)/$F29),0) -> 2.1645 | M29: =IF(M$1<$F29,$I29*(($F29-M$1)/$F29),0) -> 2.146 | N29: =IF(N$1<$F29,$I29*(($F29-N$1)/$F29),0) -> 2.1275 | O29: =IF(O$1<$F29,$I29*(($F29-O$1)/$F29),0) -> 2.109 | P29: =IF(P$1<$F29,$I29*(($F29-P$1)/$F29),0) -> 2.0905 | Q29: =IF(Q$1<$F29,$I29*(($F29-Q$1)/$F29),0) -> 2.072 | ... DY29: =IF(DY$1<$F29,$I29*(($F29-DY$1)/$F29),0) -> 0
A30: 46022 | B30: PASSIF | C30: Réserves | D30: 0 | E30: Linéaire | F30: 120 | G30: Linéaire | H30: 120 | I30: 429.975 | J30: =IF(J$1<$F30,$I30*(($F30-J$1)/$F30),0) -> 426.39188 | K30: =IF(K$1<$F30,$I30*(($F30-K$1)/$F30),0) -> 422.80875 | L30: =IF(L$1<$F30,$I30*(($F30-L$1)/$F30),0) -> 419.22563 | M30: =IF(M$1<$F30,$I30*(($F30-M$1)/$F30),0) -> 415.6425 | N30: =IF(N$1<$F30,$I30*(($F30-N$1)/$F30),0) -> 412.05938 | O30: =IF(O$1<$F30,$I30*(($F30-O$1)/$F30),0) -> 408.47625 | P30: =IF(P$1<$F30,$I30*(($F30-P$1)/$F30),0) -> 404.89312 | Q30: =IF(Q$1<$F30,$I30*(($F30-Q$1)/$F30),0) -> 401.31 | ... DY30: =IF(DY$1<$F30,$I30*(($F30-DY$1)/$F30),0) -> 0
A31: 46022 | B31: PASSIF | C31: Report à nouveau | D31: 0 | E31: Linéaire | F31: 120 | G31: Linéaire | H31: 120 | I31: 7004.934 | J31: =IF(J$1<$F31,$I31*(($F31-J$1)/$F31),0) -> 6946.5596 | K31: =IF(K$1<$F31,$I31*(($F31-K$1)/$F31),0) -> 6888.1851 | L31: =IF(L$1<$F31,$I31*(($F31-L$1)/$F31),0) -> 6829.8107 | M31: =IF(M$1<$F31,$I31*(($F31-M$1)/$F31),0) -> 6771.4362 | N31: =IF(N$1<$F31,$I31*(($F31-N$1)/$F31),0) -> 6713.0618 | O31: =IF(O$1<$F31,$I31*(($F31-O$1)/$F31),0) -> 6654.6873 | P31: =IF(P$1<$F31,$I31*(($F31-P$1)/$F31),0) -> 6596.3129 | Q31: =IF(Q$1<$F31,$I31*(($F31-Q$1)/$F31),0) -> 6537.9384 | ... DY31: =IF(DY$1<$F31,$I31*(($F31-DY$1)/$F31),0) -> 0
A32: 46022 | B32: PASSIF | C32: Résultat de l'exercice | D32: 0 | E32: Linéaire | F32: 120 | G32: Linéaire | H32: 120 | I32: 0 | J32: =IF(J$1<$F32,$I32*(($F32-J$1)/$F32),0) -> 0 | K32: =IF(K$1<$F32,$I32*(($F32-K$1)/$F32),0) -> 0 | L32: =IF(L$1<$F32,$I32*(($F32-L$1)/$F32),0) -> 0 | M32: =IF(M$1<$F32,$I32*(($F32-M$1)/$F32),0) -> 0 | N32: =IF(N$1<$F32,$I32*(($F32-N$1)/$F32),0) -> 0 | O32: =IF(O$1<$F32,$I32*(($F32-O$1)/$F32),0) -> 0 | P32: =IF(P$1<$F32,$I32*(($F32-P$1)/$F32),0) -> 0 | Q32: =IF(Q$1<$F32,$I32*(($F32-Q$1)/$F32),0) -> 0 | ... DY32: =IF(DY$1<$F32,$I32*(($F32-DY$1)/$F32),0) -> 0
A33: 46022 | B33: PASSIF | C33: Dividende | D33: 0 | E33: Linéaire | F33: 120 | G33: Linéaire | H33: 120 | I33: 0 | J33: =IF(J$1<$F33,$I33*(($F33-J$1)/$F33),0) -> 0 | K33: =IF(K$1<$F33,$I33*(($F33-K$1)/$F33),0) -> 0 | L33: =IF(L$1<$F33,$I33*(($F33-L$1)/$F33),0) -> 0 | M33: =IF(M$1<$F33,$I33*(($F33-M$1)/$F33),0) -> 0 | N33: =IF(N$1<$F33,$I33*(($F33-N$1)/$F33),0) -> 0 | O33: =IF(O$1<$F33,$I33*(($F33-O$1)/$F33),0) -> 0 | P33: =IF(P$1<$F33,$I33*(($F33-P$1)/$F33),0) -> 0 | Q33: =IF(Q$1<$F33,$I33*(($F33-Q$1)/$F33),0) -> 0 | ... DY33: =IF(DY$1<$F33,$I33*(($F33-DY$1)/$F33),0) -> 0
A34: 46022 | B34: PASSIF | C34: Total passif | I34: =I26+I24+I23+I20+I17+I25 -> 155592.33 | J34: =J17+J20+SUM(J23:J26) -> 148452.68 | K34: =K17+K20+SUM(K23:K26) -> 144610.37 | L34: =L17+L20+SUM(L23:L26) -> 141348.89 | M34: =M17+M20+SUM(M23:M26) -> 138562.95 | N34: =N17+N20+SUM(N23:N26) -> 136355.37 | O34: =O17+O20+SUM(O23:O26) -> 134655.58 | P34: =P17+P20+SUM(P23:P26) -> 133216.76 | Q34: =Q17+Q20+SUM(Q23:Q26) -> 131991.62 | ... DY34: =DY17+DY20+SUM(DY23:DY26) -> 8.1505852e-07
A35: Gap de liquidité statique | G35: =G33-G22 -> #VALUE! | H35: =H33-H22 -> 60 | I35: =I34-I16 -> -0.05598 | J35: =J34-J16 -> 76641.375 | K35: =K34-K16 -> 80916.707 | L35: =L34-L16 -> 85786.088 | M35: =M34-M16 -> 91144.265 | N35: =N34-N16 -> 97094.095 | O35: =O34-O16 -> 103565.04 | P35: =P34-P16 -> 107129.28 | ... DY35: =DY34-DY16 -> 8.1505852e-07
A39: 3) Analyse de la structure de la banque | B39: Ratio | C39: Valeurs
B40: CREANCES SUR LA CLIENTELE/Total Actifs | C40: =I9/I16 -> 0.80756084 | H40: s
B41: CREANCES SUR LES ETS DE CREDIT /Total Actifs | C41: =I6/I16 -> 0.18000203
B42: Investissements financiers / Total Actifs | C42: =I13/I16 -> 0.00017995739
B43: CPTES CREDITEURS DE LA CLIENTELE/ Total Passifs | C43: =I20/I34 -> 0.32238773
...

Sheet Bilan au 31_12_2025_BAU T
E1: E n liquidité | G1: E n taux | I1: 0 | J1: 1 | K1: 2 | L1: 3 | M1: 4 | N1: 5 | O1: 6 | P1: 7 | Q1: 8 | R1: 9 | S1: 10 | T1: 11 | U1: 12 | V1: 13 | W1: 14 | X1: 15 | Y1: 16 | Z1: 17 | AA1: 18 | AB1: 19 | AC1: 20 | AD1: 21 | AE1: 22 | AF1: 23 | AG1: 24 | AH1: 25 | AI1: 26 | AJ1: 27 | AK1: 28 | AL1: 29 | AM1: 30 | AN1: 31 | AO1: 32 | AP1: 33 | AQ1: 34 | AR1: 35 | AS1: 36 | AT1: 37 | AU1: 38 | AV1: 39 | AW1: 40 | AX1: 41 | AY1: 42 | AZ1: 43 | BA1: 44 | BB1: 45 | BC1: 46 | BD1: 47 | BE1: 48 | BF1: 49 | BG1: 50 | BH1: 51 | BI1: 52 | BJ1: 53 | BK1: 54 | BL1: 55 | BM1: 56 | BN1: 57 | BO1: 58 | BP1: 59 | BQ1: 60 | BR1: 61 | BS1: 62 | BT1: 63 | BU1: 64 | BV1: 65 | BW1: 66 | BX1: 67 | BY1: 68 | BZ1: 69 | CA1: 70 | CB1: 71 | CC1: 72 | CD1: 73 | CE1: 74 | CF1: 75 | CG1: 76 | CH1: 77 | CI1: 78 | CJ1: 79 | CK1: 80 | CL1: 81 | CM1: 82 | CN1: 83 | CO1: 84 | CP1: 85 | CQ1: 86 | CR1: 87 | CS1: 88 | CT1: 89 | CU1: 90 | CV1: 91 | CW1: 92 | CX1: 93 | CY1: 94 | CZ1: 95 | DA1: 96 | DB1: 97 | DC1: 98 | DD1: 99 | DE1: 100 | DF1: 101 | DG1: 102 | DH1: 103 | DI1: 104 | DJ1: 105 | DK1: 106 | DL1: 107 | DM1: 108 | DN1: 109 | DO1: 110 | DP1: 111 | DQ1: 112 | DR1: 113 | DS1: 114 | DT1: 115 | DU1: 116 | DV1: 117 | DW1: 118 | DX1: 119 | DY1: 120
A2: Date d’arrêté | B2: Bilan | C2: Poste du bilan | D2: Taux d'intérèt moyen | E2: Loi d'écoulement | F2: Durée moyenne (en mois) | G2: Loi d'écoulement | H2: Durée moyenne (en mois) | I2: Montant (en k€) | J2: M1 | K2: M2 | L2: M3 | M2: M4 | N2: M5 | O2: M6 | P2: M7 | Q2: M8 | R2: M9 | S2: M10 | T2: M11 | U2: M12 | V2: M13 | W2: M14 | X2: M15 | Y2: M16 | Z2: M17 | AA2: M18 | AB2: M19 | AC2: M20 | AD2: M21 | AE2: M22 | AF2: M23 | AG2: M24 | AH2: M25 | AI2: M26 | AJ2: M27 | AK2: M28 | AL2: M29 | AM2: M30 | AN2: M31 | AO2: M32 | AP2: M33 | AQ2: M34 | AR2: M35 | AS2: M36 | AT2: M37 | AU2: M38 | AV2: M39 | AW2: M40 | AX2: M41 | AY2: M42 | AZ2: M43 | BA2: M44 | BB2: M45 | BC2: M46 | BD2: M47 | BE2: M48 | BF2: M49 | BG2: M50 | BH2: M51 | BI2: M52 | BJ2: M53 | BK2: M54 | BL2: M55 | BM2: M56 | BN2: M57 | BO2: M58 | BP2: M59 | BQ2: M60 | BR2: M61 | BS2: M62 | BT2: M63 | BU2: M64 | BV2: M65 | BW2: M66 | BX2: M67 | BY2: M68 | BZ2: M69 | CA2: M70 | CB2: M71 | CC2: M72 | CD2: M73 | CE2: M74 | CF2: M75 | CG2: M76 | CH2: M77 | CI2: M78 | CJ2: M79 | CK2: M80 | CL2: M81 | CM2: M82 | CN2: M83 | CO2: M84 | CP2: M85 | CQ2: M86 | CR2: M87 | CS2: M88 | CT2: M89 | CU2: M90 | CV2: M91 | CW2: M92 | CX2: M93 | CY2: M94 | CZ2: M95 | DA2: M96 | DB2: M97 | DC2: M98 | DD2: M99 | DE2: M100 | DF2: M101 | DG2: M102 | DH2: M103 | DI2: M104 | DJ2: M105 | DK2: M106 | DL2: M107 | DM2: M108 | DN2: M109 | DO2: M110 | DP2: M111 | DQ2: M112 | DR2: M113 | DS2: M114 | DT2: M115 | DU2: M116 | DV2: M117 | DW2: M118 | DX2: M119 | DY2: M120
A3: 46022 | B3: ACTIF | C3: CAISSE, BANQUES CENTRALES | I3: 1255.124 | J3: =SUM(J4:J5) -> 1255.124 | K3: =SUM(K4:K5) -> 1255.124 | L3: =SUM(L4:L5) -> 1255.124 | M3: =SUM(M4:M5) -> 1255.124 | N3: =SUM(N4:N5) -> 1255.124 | O3: =SUM(O4:O5) -> 1255.124 | P3: =SUM(P4:P5) -> 1255.124 | Q3: =SUM(Q4:Q5) -> 1255.124 | ... DY3: =SUM(DY4:DY5) -> 0
A4: 46022 | B4: ACTIF | C4: - Caisse | D4: 0 | E4: Linéaire | F4: 60 | G4: In fine | H4: 60 | I4: 40.58686 | J4: =IF(J$1<$F4,$I4,0) -> 40.58686 | K4: =IF(K$1<$F4,$I4,0) -> 40.58686 | L4: =IF(L$1<$F4,$I4,0) -> 40.58686 | M4: =IF(M$1<$F4,$I4,0) -> 40.58686 | N4: =IF(N$1<$F4,$I4,0) -> 40.58686 | O4: =IF(O$1<$F4,$I4,0) -> 40.58686 | P4: =IF(P$1<$F4,$I4,0) -> 40.58686 | Q4: =IF(Q$1<$F4,$I4,0) -> 40.58686 | ... DY4: =IF(DY$1<$F4,$I4,0) -> 0
A5: 46022 | B5: ACTIF | C5: - Compte courant BDF | D5: 0.00040572687 | E5: Linéaire | F5: 120 | G5: Ine fine | H5: 120 | I5: 1214.5371 | J5: =IF(J$1<$F5,$I5,0) -> 1214.5371 | K5: =IF(K$1<$F5,$I5,0) -> 1214.5371 | L5: =IF(L$1<$F5,$I5,0) -> 1214.5371 | M5: =IF(M$1<$F5,$I5,0) -> 1214.5371 | N5: =IF(N$1<$F5,$I5,0) -> 1214.5371 | O5: =IF(O$1<$F5,$I5,0) -> 1214.5371 | P5: =IF(P$1<$F5,$I5,0) -> 1214.5371 | Q5: =IF(Q$1<$F5,$I5,0) -> 1214.5371 | ... DY5: =IF(DY$1<$F5,$I5,0) -> 0
A6: 46022 | B6: ACTIF | C6: CREANCES SUR LES ETS DE CREDIT | I6: 28006.945 | J6: =SUM(J7:J8) -> 24825.899 | K6: =SUM(K7:K8) -> 21644.854 | L6: =SUM(L7:L8) -> 18463.808 | M6: =SUM(M7:M8) -> 15282.762 | N6: =SUM(N7:N8) -> 12101.717 | O6: =SUM(O7:O8) -> 8920.671 | P6: =SUM(P7:P8) -> 8920.671 | Q6: =SUM(Q7:Q8) -> 8920.671 | ... DY6: =SUM(DY7:DY8) -> 0
A7: 46022 | B7: ACTIF | C7: - A vue | D7: 0 | E7: Linéaire | F7: 6 | G7: Linéaire | H7: 6 | I7: 19086.274 | J7: =IF(J$1<$F7,$I7*(($F7-J$1)/$F7),0) -> 15905.228 | K7: =IF(K$1<$F7,$I7*(($F7-K$1)/$F7),0) -> 12724.183 | L7: =IF(L$1<$F7,$I7*(($F7-L$1)/$F7),0) -> 9543.137 | M7: =IF(M$1<$F7,$I7*(($F7-M$1)/$F7),0) -> 6362.0913 | N7: =IF(N$1<$F7,$I7*(($F7-N$1)/$F7),0) -> 3181.0457 | O7: =IF(O$1<$F7,$I7*(($F7-O$1)/$F7),0) -> 0 | P7: =IF(P$1<$F7,$I7*(($F7-P$1)/$F7),0) -> 0 | Q7: =IF(Q$1<$F7,$I7*(($F7-Q$1)/$F7),0) -> 0 | ... DY7: =IF(DY$1<$F7,$I7*(($F7-DY$1)/$F7),0) -> 0
A8: 46022 | B8: ACTIF | C8: - A terme | D8: 0.02489751 | E8: In fine | F8: 12 | G8: In fine | H8: 12 | I8: 8920.671 | J8: =IF(J$1<$F8,$I8,0) -> 8920.671 | K8: =IF(K$1<$F8,$I8,0) -> 8920.671 | L8: =IF(L$1<$F8,$I8,0) -> 8920.671 | M8: =IF(M$1<$F8,$I8,0) -> 8920.671 | N8: =IF(N$1<$F8,$I8,0) -> 8920.671 | O8: =IF(O$1<$F8,$I8,0) -> 8920.671 | P8: =IF(P$1<$F8,$I8,0) -> 8920.671 | Q8: =IF(Q$1<$F8,$I8,0) -> 8920.671 | ... DY8: =IF(DY$1<$F8,$I8,0) -> 0
A9: 46022 | B9: ACTIF | C9: CREANCES SUR LA CLIENTELE | I9: 125650.32 | J9: =SUM(J10:J12) -> 45066.509 | K9: =SUM(K10:K12) -> 40146.149 | L9: =SUM(L10:L12) -> 35212.566 | M9: =SUM(M10:M12) -> 30265.727 | N9: =SUM(N10:N12) -> 25305.594 | O9: =SUM(O10:O12) -> 20332.132 | P9: =SUM(P10:P12) -> 15345.305 | Q9: =SUM(Q10:Q12) -> 10345.078 | ... DY9: =SUM(DY10:DY12) -> 0
A10: 46022 | B10: ACTIF | C10: - Créances commerciales | D10: 0.048443032 | E10: Constant | F10: 60 | G10: Constant | H10: 60 | I10: 358.117 | J10: =IF(J$1<$F10,(I10*(1+($D10/12)))-(-PMT($D10/12,$F10,$I10)),0) -> 352.8301 | K10: =IF(K$1<$F10,(J10*(1+($D10/12)))-(-PMT($D10/12,$F10,$I10)),0) -> 347.52185 | L10: =IF(L$1<$F10,(K10*(1+($D10/12)))-(-PMT($D10/12,$F10,$I10)),0) -> 342.19217 | M10: =IF(M$1<$F10,(L10*(1+($D10/12)))-(-PMT($D10/12,$F10,$I10)),0) -> 336.84098 | N10: =IF(N$1<$F10,(M10*(1+($D10/12)))-(-PMT($D10/12,$F10,$I10)),0) -> 331.46818 | O10: =IF(O$1<$F10,(N10*(1+($D10/12)))-(-PMT($D10/12,$F10,$I10)),0) -> 326.0737 | P10: =IF(P$1<$F10,(O10*(1+($D10/12)))-(-PMT($D10/12,$F10,$I10)),0) -> 320.65744 | Q10: =IF(Q$1<$F10,(P10*(1+($D10/12)))-(-PMT($D10/12,$F10,$I10)),0) -> 315.21931 | ... DY10: =IF(DY$1<$F10,(DX10*(1+($D10/12)))-(-PMT($D10/12,$F10,$I10)),0) -> 0
A11: 46022 | B11: ACTIF | C11: - Autres concours à la clientèle | D11: 0.032228873 | E11: Constant | F11: 10 | G11: Constant | H11: 10 | I11: 49615.566 | J11: =IF(J$1<$F11,(I11*(1+($D11/12)))-(-PMT($D11/12,$F11,$I11)),0) -> 44713.679 | K11: =IF(K$1<$F11,(J11*(1+($D11/12)))-(-PMT($D11/12,$F11,$I11)),0) -> 39798.627 | L11: =IF(L$1<$F11,(K11*(1+($D11/12)))-(-PMT($D11/12,$F11,$I11)),0) -> 34870.374 | M11: =IF(M$1<$F11,(L11*(1+($D11/12)))-(-PMT($D11/12,$F11,$I11)),0) -> 29928.886 | N11: =IF(N$1<$F11,(M11*(1+($D11/12)))-(-PMT($D11/12,$F11,$I11)),0) -> 24974.125 | O11: =IF(O$1<$F11,(N11*(1+($D11/12)))-(-PMT($D11/12,$F11,$I11)),0) -> 20006.058 | P11: =IF(P$1<$F11,(O11*(1+($D11/12)))-(-PMT($D11/12,$F11,$I11)),0) -> 15024.648 | Q11: =IF(Q$1<$F11,(P11*(1+($D11/12)))-(-PMT($D11/12,$F11,$I11)),0) -> 10029.858 | ... DY11: =IF(DY$1<$F11,(DX11*(1+($D11/12)))-(-PMT($D11/12,$F11,$I11)),0) -> 0
A12: 46022 | B12: ACTIF | C12: - Comptes ordinaires débiteurs | D12: 0.039912213 | E12: In fine | F12: 1 | G12: In fine | H12: 1 | I12: 75676.636 | J12: =IF(J$1<$F12,$I12,0) -> 0 | K12: =IF(K$1<$F12,$I12,0) -> 0 | L12: =IF(L$1<$F12,$I12,0) -> 0 | M12: =IF(M$1<$F12,$I12,0) -> 0 | N12: =IF(N$1<$F12,$I12,0) -> 0 | O12: =IF(O$1<$F12,$I12,0) -> 0 | P12: =IF(P$1<$F12,$I12,0) -> 0 | Q12: =IF(Q$1<$F12,$I12,0) -> 0 | ... DY12: =IF(DY$1<$F12,$I12,0) -> 0
A13: 46022 | B13: ACTIF | C13: Investissements financiers | D13: 0.05 | E13: Ine fine | F13: 84 | G13: Ine fine | H13: 84 | I13: 28 | J13: =IF(J$1<$F13,$I13,0) -> 28 | K13: =IF(K$1<$F13,$I13,0) -> 28 | L13: =IF(L$1<$F13,$I13,0) -> 28 | M13: =IF(M$1<$F13,$I13,0) -> 28 | N13: =IF(N$1<$F13,$I13,0) -> 28 | O13: =IF(O$1<$F13,$I13,0) -> 28 | P13: =IF(P$1<$F13,$I13,0) -> 28 | Q13: =IF(Q$1<$F13,$I13,0) -> 28 | ... DY13: =IF(DY$1<$F13,$I13,0) -> 0
A14: 46022 | B14: ACTIF | C14: Immobilisations corporelles et incorporelles | E14: Linéaire | F14: 120 | G14: Linéaire | H14: 120 | I14: 82 | J14: =IF(J$1<$F14,$I14*(($F14-J$1)/$F14),0) -> 81.316667 | K14: =IF(K$1<$F14,$I14*(($F14-K$1)/$F14),0) -> 80.633333 | L14: =IF(L$1<$F14,$I14*(($F14-L$1)/$F14),0) -> 79.95 | M14: =IF(M$1<$F14,$I14*(($F14-M$1)/$F14),0) -> 79.266667 | N14: =IF(N$1<$F14,$I14*(($F14-N$1)/$F14),0) -> 78.583333 | O14: =IF(O$1<$F14,$I14*(($F14-O$1)/$F14),0) -> 77.9 | P14: =IF(P$1<$F14,$I14*(($F14-P$1)/$F14),0) -> 77.216667 | Q14: =IF(Q$1<$F14,$I14*(($F14-Q$1)/$F14),0) -> 76.533333 | ... DY14: =IF(DY$1<$F14,$I14*(($F14-DY$1)/$F14),0) -> 0
A15: 46022 | B15: ACTIF | C15: Autres actifs | E15: Linéaire | F15: 120 | G15: Linéaire | H15: 120 | I15: 570 | J15: =IF(J$1<$F15,$I15*(($F15-J$1)/$F15),0) -> 565.25 | K15: =IF(K$1<$F15,$I15*(($F15-K$1)/$F15),0) -> 560.5 | L15: =IF(L$1<$F15,$I15*(($F15-L$1)/$F15),0) -> 555.75 | M15: =IF(M$1<$F15,$I15*(($F15-M$1)/$F15),0) -> 551 | N15: =IF(N$1<$F15,$I15*(($F15-N$1)/$F15),0) -> 546.25 | O15: =IF(O$1<$F15,$I15*(($F15-O$1)/$F15),0) -> 541.5 | P15: =IF(P$1<$F15,$I15*(($F15-P$1)/$F15),0) -> 536.75 | Q15: =IF(Q$1<$F15,$I15*(($F15-Q$1)/$F15),0) -> 532 | ... DY15: =IF(DY$1<$F15,$I15*(($F15-DY$1)/$F15),0) -> 0
A16: 46022 | B16: ACTIF | C16: Total actif | I16: =I3+I6+I9+I13+I14+I15 -> 155592.39 | J16: =J3+J6+J9+SUM(J13:J15) -> 71822.099 | K16: =K3+K6+K9+SUM(K13:K15) -> 63715.26 | L16: =L3+L6+L9+SUM(L13:L15) -> 55595.198 | M16: =M3+M6+M9+SUM(M13:M15) -> 47461.88 | N16: =N3+N6+N9+SUM(N13:N15) -> 39315.267 | O16: =O3+O6+O9+SUM(O13:O15) -> 31155.327 | P16: =P3+P6+P9+SUM(P13:P15) -> 26163.067 | Q16: =Q3+Q6+Q9+SUM(Q13:Q15) -> 21157.406 | ... DY16: =DY3+DY6+DY9+SUM(DY13:DY15) -> 0
A17: 46022 | B17: PASSIF | C17: DETTES ENVERS ETS DE CREDIT | I17: =I18+I19 -> 74095.3 | J17: =SUM(J18:J19) -> 74095.3 | K17: =SUM(K18:K19) -> 74095.3 | L17: =SUM(L18:L19) -> 74095.3 | M17: =SUM(M18:M19) -> 72205.1 | N17: =SUM(N18:N19) -> 72205.1 | O17: =SUM(O18:O19) -> 72205.1 | P17: =SUM(P18:P19) -> 72205.1 | Q17: =SUM(Q18:Q19) -> 72205.1 | ... DY17: =SUM(DY18:DY19) -> 0
A18: 46022 | B18: PASSIF | C18: - A vue | D18: 0 | E18: 90%-20%*t, t<=4mois | F18: 4 | G18: In fine | H18: 4 | I18: 1890.2 | J18: =IF(J$1<$F18,$I18,0) -> 1890.2 | K18: =IF(K$1<$F18,$I18,0) -> 1890.2 | L18: =IF(L$1<$F18,$I18,0) -> 1890.2 | M18: =IF(M$1<$F18,$I18,0) -> 0 | N18: =IF(N$1<$F18,$I18,0) -> 0 | O18: =IF(O$1<$F18,$I18,0) -> 0 | P18: =IF(P$1<$F18,$I18,0) -> 0 | Q18: =IF(Q$1<$F18,$I18,0) -> 0 | ... DY18: =IF(DY$1<$F18,$I18,0) -> 0
A19: 46022 | B19: PASSIF | C19: - A terme | D19: 0.0138965 | E19: Ine fine | F19: 24 | G19: Ine fine | H19: 24 | I19: 72205.1 | J19: =IF(J$1<$F19,$I19,0) -> 72205.1 | K19: =IF(K$1<$F19,$I19,0) -> 72205.1 | L19: =IF(L$1<$F19,$I19,0) -> 72205.1 | M19: =IF(M$1<$F19,$I19,0) -> 72205.1 | N19: =IF(N$1<$F19,$I19,0) -> 72205.1 | O19: =IF(O$1<$F19,$I19,0) -> 72205.1 | P19: =IF(P$1<$F19,$I19,0) -> 72205.1 | Q19: =IF(Q$1<$F19,$I19,0) -> 72205.1 | ... DY19: =IF(DY$1<$F19,$I19,0) -> 0
A20: 46022 | B20: PASSIF | C20: CPTES CREDITEURS DE LA CLIENTELE | I20: 50161.059 | J20: =SUM(J21:J22) -> 49961.15 | K20: =SUM(K21:K22) -> 49761.241 | L20: =SUM(L21:L22) -> 49561.332 | M20: =SUM(M21:M22) -> 49361.423 | N20: =SUM(N21:N22) -> 49161.513 | O20: =SUM(O21:O22) -> 48961.604 | P20: =SUM(P21:P22) -> 48761.695 | Q20: =SUM(Q21:Q22) -> 48561.786 | ... DY20: =SUM(DY21:DY22) -> 0
A21: 46022 | B21: PASSIF | C21: - A vue | D21: 0 | E21: 90%*exp(-20%*t), t<=120 mois | F21: 120 | G21: Linéaire | H21: 120 | I21: 23989.094 | J21: =IF(J$1<$F21,$I21*(($F21-J$1)/$F21),0) -> 23789.185 | K21: =IF(K$1<$F21,$I21*(($F21-K$1)/$F21),0) -> 23589.276 | L21: =IF(L$1<$F21,$I21*(($F21-L$1)/$F21),0) -> 23389.367 | M21: =IF(M$1<$F21,$I21*(($F21-M$1)/$F21),0) -> 23189.458 | N21: =IF(N$1<$F21,$I21*(($F21-N$1)/$F21),0) -> 22989.548 | O21: =IF(O$1<$F21,$I21*(($F21-O$1)/$F21),0) -> 22789.639 | P21: =IF(P$1<$F21,$I21*(($F21-P$1)/$F21),0) -> 22589.73 | Q21: =IF(Q$1<$F21,$I21*(($F21-Q$1)/$F21),0) -> 22389.821 | ... DY21: =IF(DY$1<$F21,$I21*(($F21-DY$1)/$F21),0) -> 0
A22: 46022 | B22: PASSIF | C22: - A terme | D22: 0.0083386457 | E22: In fine | F22: 60 | G22: In fine | H22: 60 | I22: 26171.965 | J22: =IF(J$1<$F22,$I22,0) -> 26171.965 | K22: =IF(K$1<$F22,$I22,0) -> 26171.965 | L22: =IF(L$1<$F22,$I22,0) -> 26171.965 | M22: =IF(M$1<$F22,$I22,0) -> 26171.965 | N22: =IF(N$1<$F22,$I22,0) -> 26171.965 | O22: =IF(O$1<$F22,$I22,0) -> 26171.965 | P22: =IF(P$1<$F22,$I22,0) -> 26171.965 | Q22: =IF(Q$1<$F22,$I22,0) -> 26171.965 | ... DY22: =IF(DY$1<$F22,$I22,0) -> 0
A23: 46022 | B23: PASSIF | C23: Autres passifs | D23: 0 | E23: Linéaire | F23: 120 | G23: Linéaire | H23: 120 | I23: 2297.337 | J23: =IF(J$1<$F23,$I23*(($F23-J$1)/$F23),0) -> 2278.1925 | K23: =IF(K$1<$F23,$I23*(($F23-K$1)/$F23),0) -> 2259.048 | L23: =IF(L$1<$F23,$I23*(($F23-L$1)/$F23),0) -> 2239.9036 | M23: =IF(M$1<$F23,$I23*(($F23-M$1)/$F23),0) -> 2220.7591 | N23: =IF(N$1<$F23,$I23*(($F23-N$1)/$F23),0) -> 2201.6146 | O23: =IF(O$1<$F23,$I23*(($F23-O$1)/$F23),0) -> 2182.4702 | P23: =IF(P$1<$F23,$I23*(($F23-P$1)/$F23),0) -> 2163.3257 | Q23: =IF(Q$1<$F23,$I23*(($F23-Q$1)/$F23),0) -> 2144.1812 | ... DY23: =IF(DY$1<$F23,$I23*(($F23-DY$1)/$F23),0) -> 0
A24: 46022 | B24: PASSIF | C24: Provisions pour risques et charges | D24: 0 | E24: Linéaire | F24: 120 | G24: Linéaire | H24: 120 | I24: 2994.787 | J24: =IF(J$1<$F24,$I24*(($F24-J$1)/$F24),0) -> 2969.8304 | K24: =IF(K$1<$F24,$I24*(($F24-K$1)/$F24),0) -> 2944.8739 | L24: =IF(L$1<$F24,$I24*(($F24-L$1)/$F24),0) -> 2919.9173 | M24: =IF(M$1<$F24,$I24*(($F24-M$1)/$F24),0) -> 2894.9608 | N24: =IF(N$1<$F24,$I24*(($F24-N$1)/$F24),0) -> 2870.0042 | O24: =IF(O$1<$F24,$I24*(($F24-O$1)/$F24),0) -> 2845.0476 | P24: =IF(P$1<$F24,$I24*(($F24-P$1)/$F24),0) -> 2820.0911 | Q24: =IF(Q$1<$F24,$I24*(($F24-Q$1)/$F24),0) -> 2795.1345 | ... DY24: =IF(DY$1<$F24,$I24*(($F24-DY$1)/$F24),0) -> 0
A25: 46022 | B25: PASSIF | C25: Financement LT | D25: 0.035 | E25: In fine | F25: 72 | G25: In fine | H25: 72 | I25: 130 | J25: =IF(J$1<$F25,$I25,0) -> 130 | K25: =IF(K$1<$F25,$I25,0) -> 130 | L25: =IF(L$1<$F25,$I25,0) -> 130 | M25: =IF(M$1<$F25,$I25,0) -> 130 | N25: =IF(N$1<$F25,$I25,0) -> 130 | O25: =IF(O$1<$F25,$I25,0) -> 130 | P25: =IF(P$1<$F25,$I25,0) -> 130 | Q25: =IF(Q$1<$F25,$I25,0) -> 130 | ... DY25: =IF(DY$1<$F25,$I25,0) -> 0
A26: 46022 | B26: PASSIF | C26: Capitaux propres | I26: 25913.849 | J26: =SUM(J27:J33) -> 25697.9 | K26: =SUM(K27:K33) -> 25481.952 | L26: =SUM(L27:L33) -> 25266.003 | M26: =SUM(M27:M33) -> 25050.054 | N26: =SUM(N27:N33) -> 24834.105 | O26: =SUM(O27:O33) -> 24618.157 | P26: =SUM(P27:P33) -> 24402.208 | Q26: =SUM(Q27:Q33) -> 24186.259 | ... DY26: =SUM(DY27:DY33) -> 0
A27: 46022 | B27: PASSIF | C27: FRBG | D27: 0 | E27: Linéaire | F27: 120 | G27: Linéaire | H27: 120 | I27: 476.541 | J27: =IF(J$1<$F27,$I27*(($F27-J$1)/$F27),0) -> 472.56983 | K27: =IF(K$1<$F27,$I27*(($F27-K$1)/$F27),0) -> 468.59865 | L27: =IF(L$1<$F27,$I27*(($F27-L$1)/$F27),0) -> 464.62748 | M27: =IF(M$1<$F27,$I27*(($F27-M$1)/$F27),0) -> 460.6563 | N27: =IF(N$1<$F27,$I27*(($F27-N$1)/$F27),0) -> 456.68513 | O27: =IF(O$1<$F27,$I27*(($F27-O$1)/$F27),0) -> 452.71395 | P27: =IF(P$1<$F27,$I27*(($F27-P$1)/$F27),0) -> 448.74277 | Q27: =IF(Q$1<$F27,$I27*(($F27-Q$1)/$F27),0) -> 444.7716 | ... DY27: =IF(DY$1<$F27,$I27*(($F27-DY$1)/$F27),0) -> 0
A28: 46022 | B28: PASSIF | C28: Capital souscrit | D28: 0 | E28: Linéaire | F28: 120 | G28: Linéaire | H28: 120 | I28: 18000.179 | J28: =IF(J$1<$F28,$I28*(($F28-J$1)/$F28),0) -> 17850.178 | K28: =IF(K$1<$F28,$I28*(($F28-K$1)/$F28),0) -> 17700.176 | L28: =IF(L$1<$F28,$I28*(($F28-L$1)/$F28),0) -> 17550.175 | M28: =IF(M$1<$F28,$I28*(($F28-M$1)/$F28),0) -> 17400.173 | N28: =IF(N$1<$F28,$I28*(($F28-N$1)/$F28),0) -> 17250.172 | O28: =IF(O$1<$F28,$I28*(($F28-O$1)/$F28),0) -> 17100.17 | P28: =IF(P$1<$F28,$I28*(($F28-P$1)/$F28),0) -> 16950.169 | Q28: =IF(Q$1<$F28,$I28*(($F28-Q$1)/$F28),0) -> 16800.167 | ... DY28: =IF(DY$1<$F28,$I28*(($F28-DY$1)/$F28),0) -> 0
A29: 46022 | B29: PASSIF | C29: Prime d'émission | D29: 0 | E29: Linéaire | F29: 120 | G29: Linéaire | H29: 120 | I29: 2.22 | J29: =IF(J$1<$F29,$I29*(($F29-J$1)/$F29),0) -> 2.2015 | K29: =IF(K$1<$F29,$I29*(($F29-K$1)/$F29),0) -> 2.183 | L29: =IF(L$1<$F29,$I29*(($F29-L$1)/$F29),0) -> 2.1645 | M29: =IF(M$1<$F29,$I29*(($F29-M$1)/$F29),0) -> 2.146 | N29: =IF(N$1<$F29,$I29*(($F29-N$1)/$F29),0) -> 2.1275 | O29: =IF(O$1<$F29,$I29*(($F29-O$1)/$F29),0) -> 2.109 | P29: =IF(P$1<$F29,$I29*(($F29-P$1)/$F29),0) -> 2.0905 | Q29: =IF(Q$1<$F29,$I29*(($F29-Q$1)/$F29),0) -> 2.072 | ... DY29: =IF(DY$1<$F29,$I29*(($F29-DY$1)/$F29),0) -> 0
A30: 46022 | B30: PASSIF | C30: Réserves | D30: 0 | E30: Linéaire | F30: 120 | G30: Linéaire | H30: 120 | I30: 429.975 | J30: =IF(J$1<$F30,$I30*(($F30-J$1)/$F30),0) -> 426.39188 | K30: =IF(K$1<$F30,$I30*(($F30-K$1)/$F30),0) -> 422.80875 | L30: =IF(L$1<$F30,$I30*(($F30-L$1)/$F30),0) -> 419.22563 | M30: =IF(M$1<$F30,$I30*(($F30-M$1)/$F30),0) -> 415.6425 | N30: =IF(N$1<$F30,$I30*(($F30-N$1)/$F30),0) -> 412.05938 | O30: =IF(O$1<$F30,$I30*(($F30-O$1)/$F30),0) -> 408.47625 | P30: =IF(P$1<$F30,$I30*(($F30-P$1)/$F30),0) -> 404.89312 | Q30: =IF(Q$1<$F30,$I30*(($F30-Q$1)/$F30),0) -> 401.31 | ... DY30: =IF(DY$1<$F30,$I30*(($F30-DY$1)/$F30),0) -> 0
A31: 46022 | B31: PASSIF | C31: Report à nouveau | D31: 0 | E31: Linéaire | F31: 120 | G31: Linéaire | H31: 120 | I31: 7004.934 | J31: =IF(J$1<$F31,$I31*(($F31-J$1)/$F31),0) -> 6946.5596 | K31: =IF(K$1<$F31,$I31*(($F31-K$1)/$F31),0) -> 6888.1851 | L31: =IF(L$1<$F31,$I31*(($F31-L$1)/$F31),0) -> 6829.8107 | M31: =IF(M$1<$F31,$I31*(($F31-M$1)/$F31),0) -> 6771.4362 | N31: =IF(N$1<$F31,$I31*(($F31-N$1)/$F31),0) -> 6713.0618 | O31: =IF(O$1<$F31,$I31*(($F31-O$1)/$F31),0) -> 6654.6873 | P31: =IF(P$1<$F31,$I31*(($F31-P$1)/$F31),0) -> 6596.3129 | Q31: =IF(Q$1<$F31,$I31*(($F31-Q$1)/$F31),0) -> 6537.9384 | ... DY31: =IF(DY$1<$F31,$I31*(($F31-DY$1)/$F31),0) -> 0
A32: 46022 | B32: PASSIF | C32: Résultat de l'exercice | D32: 0 | E32: Linéaire | F32: 120 | G32: Linéaire | H32: 120 | I32: 0 | J32: =IF(J$1<$F32,$I32*(($F32-J$1)/$F32),0) -> 0 | K32: =IF(K$1<$F32,$I32*(($F32-K$1)/$F32),0) -> 0 | L32: =IF(L$1<$F32,$I32*(($F32-L$1)/$F32),0) -> 0 | M32: =IF(M$1<$F32,$I32*(($F32-M$1)/$F32),0) -> 0 | N32: =IF(N$1<$F32,$I32*(($F32-N$1)/$F32),0) -> 0 | O32: =IF(O$1<$F32,$I32*(($F32-O$1)/$F32),0) -> 0 | P32: =IF(P$1<$F32,$I32*(($F32-P$1)/$F32),0) -> 0 | Q32: =IF(Q$1<$F32,$I32*(($F32-Q$1)/$F32),0) -> 0 | ... DY32: =IF(DY$1<$F32,$I32*(($F32-DY$1)/$F32),0) -> 0
A33: 46022 | B33: PASSIF | C33: Dividende | D33: 0 | E33: Linéaire | F33: 120 | G33: Linéaire | H33: 120 | I33: 0 | J33: =IF(J$1<$F33,$I33*(($F33-J$1)/$F33),0) -> 0 | K33: =IF(K$1<$F33,$I33*(($F33-K$1)/$F33),0) -> 0 | L33: =IF(L$1<$F33,$I33*(($F33-L$1)/$F33),0) -> 0 | M33: =IF(M$1<$F33,$I33*(($F33-M$1)/$F33),0) -> 0 | N33: =IF(N$1<$F33,$I33*(($F33-N$1)/$F33),0) -> 0 | O33: =IF(O$1<$F33,$I33*(($F33-O$1)/$F33),0) -> 0 | P33: =IF(P$1<$F33,$I33*(($F33-P$1)/$F33),0) -> 0 | Q33: =IF(Q$1<$F33,$I33*(($F33-Q$1)/$F33),0) -> 0 | ... DY33: =IF(DY$1<$F33,$I33*(($F33-DY$1)/$F33),0) -> 0
A34: 46022 | B34: PASSIF | C34: Total passif | I34: =I26+I24+I23+I20+I17+I25 -> 155592.33 | J34: =J17+J20+SUM(J23:J26) -> 155132.37 | K34: =K17+K20+SUM(K23:K26) -> 154672.41 | L34: =L17+L20+SUM(L23:L26) -> 154212.46 | M34: =M17+M20+SUM(M23:M26) -> 151862.3 | N34: =N17+N20+SUM(N23:N26) -> 151402.34 | O34: =O17+O20+SUM(O23:O26) -> 150942.38 | P34: =P17+P20+SUM(P23:P26) -> 150482.42 | Q34: =Q17+Q20+SUM(Q23:Q26) -> 150022.46 | ... DY34: =DY17+DY20+SUM(DY23:DY26) -> 0
A35: Gap de taux fixé | I35: =I34-I16 -> -0.05598 | J35: =J34-J16 -> 83310.274 | K35: =K34-K16 -> 90957.154 | L35: =L34-L16 -> 98617.257 | M35: =M34-M16 -> 104400.42 | N35: =N34-N16 -> 112087.07 | O35: =O34-O16 -> 119787.05 | P35: =P34-P16 -> 124319.35 | ... DY35: =DY34-DY16 -> 0
C42: *ETS : Etablissement
C43: *FRBG : Fonds pour Risques Bancaires Généraux

Sheet BAU_Liquidité_Dynamique
E1: E n liquidité | G1: E n taux | I1: 0 | J1: 1 | K1: 2 | L1: 3 | M1: 4 | N1: 5 | O1: 6 | P1: 7 | Q1: 8 | R1: 9 | S1: 10 | T1: 11 | U1: 12 | V1: 13 | W1: 14 | X1: 15 | Y1: 16 | Z1: 17 | AA1: 18 | AB1: 19 | AC1: 20 | AD1: 21 | AE1: 22 | AF1: 23 | AG1: 24 | AH1: 25 | AI1: 26 | AJ1: 27 | AK1: 28 | AL1: 29 | AM1: 30 | AN1: 31 | AO1: 32 | AP1: 33 | AQ1: 34 | AR1: 35 | AS1: 36 | AT1: 37 | AU1: 38 | AV1: 39 | AW1: 40 | AX1: 41 | AY1: 42 | AZ1: 43 | BA1: 44 | BB1: 45 | BC1: 46 | BD1: 47 | BE1: 48 | BF1: 49 | BG1: 50 | BH1: 51 | BI1: 52 | BJ1: 53 | BK1: 54 | BL1: 55 | BM1: 56 | BN1: 57 | BO1: 58 | BP1: 59 | BQ1: 60 | BR1: 61 | BS1: 62 | BT1: 63 | BU1: 64 | BV1: 65 | BW1: 66 | BX1: 67 | BY1: 68 | BZ1: 69 | CA1: 70 | CB1: 71 | CC1: 72 | CD1: 73 | CE1: 74 | CF1: 75 | CG1: 76 | CH1: 77 | CI1: 78 | CJ1: 79 | CK1: 80 | CL1: 81 | CM1: 82 | CN1: 83 | CO1: 84 | CP1: 85 | CQ1: 86 | CR1: 87 | CS1: 88 | CT1: 89 | CU1: 90 | CV1: 91 | CW1: 92 | CX1: 93 | CY1: 94 | CZ1: 95 | DA1: 96 | DB1: 97 | DC1: 98 | DD1: 99 | DE1: 100 | DF1: 101 | DG1: 102 | DH1: 103 | DI1: 104 | DJ1: 105 | DK1: 106 | DL1: 107 | DM1: 108 | DN1: 109 | DO1: 110 | DP1: 111 | DQ1: 112 | DR1: 113 | DS1: 114 | DT1: 115 | DU1: 116 | DV1: 117 | DW1: 118 | DX1: 119 | DY1: 120
A2: Date d’arrêté | B2: Bilan | C2: Poste du bilan | D2: Taux d'intérèt moyen | E2: Loi d'écoulement | F2: Durée moyenne (en mois) | G2: Loi d'écoulement | H2: Durée moyenne (en mois) | I2: Montant (en k€) | J2: M1 | K2: M2 | L2: M3 | M2: M4 | N2: M5 | O2: M6 | P2: M7 | Q2: M8 | R2: M9 | S2: M10 | T2: M11 | U2: M12 | V2: M13 | W2: M14 | X2: M15 | Y2: M16 | Z2: M17 | AA2: M18 | AB2: M19 | AC2: M20 | AD2: M21 | AE2: M22 | AF2: M23 | AG2: M24 | AH2: M25 | AI2: M26 | AJ2: M27 | AK2: M28 | AL2: M29 | AM2: M30 | AN2: M31 | AO2: M32 | AP2: M33 | AQ2: M34 | AR2: M35 | AS2: M36 | AT2: M37 | AU2: M38 | AV2: M39 | AW2: M40 | AX2: M41 | AY2: M42 | AZ2: M43 | BA2: M44 | BB2: M45 | BC2: M46 | BD2: M47 | BE2: M48 | BF2: M49 | BG2: M50 | BH2: M51 | BI2: M52 | BJ2: M53 | BK2: M54 | BL2: M55 | BM2: M56 | BN2: M57 | BO2: M58 | BP2: M59 | BQ2: M60 | BR2: M61 | BS2: M62 | BT2: M63 | BU2: M64 | BV2: M65 | BW2: M66 | BX2: M67 | BY2: M68 | BZ2: M69 | CA2: M70 | CB2: M71 | CC2: M72 | CD2: M73 | CE2: M74 | CF2: M75 | CG2: M76 | CH2: M77 | CI2: M78 | CJ2: M79 | CK2: M80 | CL2: M81 | CM2: M82 | CN2: M83 | CO2: M84 | CP2: M85 | CQ2: M86 | CR2: M87 | CS2: M88 | CT2: M89 | CU2: M90 | CV2: M91 | CW2: M92 | CX2: M93 | CY2: M94 | CZ2: M95 | DA2: M96 | DB2: M97 | DC2: M98 | DD2: M99 | DE2: M100 | DF2: M101 | DG2: M102 | DH2: M103 | DI2: M104 | DJ2: M105 | DK2: M106 | DL2: M107 | DM2: M108 | DN2: M109 | DO2: M110 | DP2: M111 | DQ2: M112 | DR2: M113 | DS2: M114 | DT2: M115 | DU2: M116 | DV2: M117 | DW2: M118 | DX2: M119 | DY2: M120
A3: 46022 | B3: ACTIF | C3: CAISSE, BANQUES CENTRALES | I3: =I4+I8 -> 1255.124 | J3: =SUM(J4:J8) -> 1244.3264 | K3: =SUM(K4:K8) -> 1233.5288 | L3: =SUM(L4:L8) -> 1222.7312 | M3: =SUM(M4:M8) -> 1211.9336 | N3: =SUM(N4:N8) -> 1201.136 | O3: =SUM(O4:O8) -> 1190.3384 | P3: =SUM(P4:P8) -> 1179.5408 | Q3: =SUM(Q4:Q8) -> 1168.7433 | ... DY3: =SUM(DY4:DY8) -> 0
A4: 46022 | B4: ACTIF | C4: - Caisse | D4: 0 | E4: Linéaire | F4: 60 | G4: In fine | H4: 60 | I4: 40.58686 | J4: =IF(J$1<$F4,$I4*(($F4-J$1)/$F4),0) -> 39.910412 | K4: =IF(K$1<$F4,$I4*(($F4-K$1)/$F4),0) -> 39.233965 | L4: =IF(L$1<$F4,$I4*(($F4-L$1)/$F4),0) -> 38.557517 | M4: =IF(M$1<$F4,$I4*(($F4-M$1)/$F4),0) -> 37.881069 | N4: =IF(N$1<$F4,$I4*(($F4-N$1)/$F4),0) -> 37.204622 | O4: =IF(O$1<$F4,$I4*(($F4-O$1)/$F4),0) -> 36.528174 | P4: =IF(P$1<$F4,$I4*(($F4-P$1)/$F4),0) -> 35.851726 | Q4: =IF(Q$1<$F4,$I4*(($F4-Q$1)/$F4),0) -> 35.175279 | ... DY4: =IF(DY$1<$F4,$I4*(($F4-DY$1)/$F4),0) -> 0
C5: Nouvelles productions 2026 | U5: ='Plan Moyen Terme (PMT)'!C4-BAU_Liquidité_Dynamique!U4 -> -5.783928 | V5: =IF(AND(U1<V$1, V$1<=$F4),$U5*($F4-V$1)/($F4-$U1),0) -> -5.6634295 | W5: =IF(AND(V1<W$1, W$1<=$F4),$U5*($F4-W$1)/($F4-$U1),0) -> -5.542931 | X5: =IF(AND(W1<X$1, X$1<=$F4),$U5*($F4-X$1)/($F4-$U1),0) -> -5.4224325 | Y5: =IF(AND(X1<Y$1, Y$1<=$F4),$U5*($F4-Y$1)/($F4-$U1),0) -> -5.301934 | Z5: =IF(AND(Y1<Z$1, Z$1<=$F4),$U5*($F4-Z$1)/($F4-$U1),0) -> -5.1814355 | AA5: =IF(AND(Z1<AA$1, AA$1<=$F4),$U5*($F4-AA$1)/($F4-$U1),0) -> -5.060937 | AB5: =IF(AND(AA1<AB$1, AB$1<=$F4),$U5*($F4-AB$1)/($F4-$U1),0) -> -4.9404385 | AC5: =IF(AND(AB1<AC$1, AC$1<=$F4),$U5*($F4-AC$1)/($F4-$U1),0) -> -4.81994 | ... BQ5: =IF(AND(BP1<BQ$1, BQ$1<=$F4),$U5*($F4-BQ$1)/($F4-$U1),0) -> 0 | BR5: =IF(BR$1<$F4-$U1,$U5*($F4-BR$1)/($F4-$U1),0) -> 0 | BS5: =IF(BS$1<$F4-$U1,$U5*($F4-BS$1)/($F4-$U1),0) -> 0 | BT5: =IF(BT$1<$F4-$U1,$U5*($F4-BT$1)/($F4-$U1),0) -> 0 | BU5: =IF(BU$1<$F4-$U1,$U5*($F4-BU$1)/($F4-$U1),0) -> 0 | BV5: =IF(BV$1<$F4-$U1,$U5*($F4-BV$1)/($F4-$U1),0) -> 0 | BW5: =IF(BW$1<$F4-$U1,$U5*($F4-BW$1)/($F4-$U1),0) -> 0 | BX5: =IF(BX$1<$F4-$U1,$U5*($F4-BX$1)/($F4-$U1),0) -> 0 | BY5: =IF(BY$1<$F4-$U1,$U5*($F4-BY$1)/($F4-$U1),0) -> 0 | ... DY5: =IF(DY$1<$F4-$U1,$U5*($F4-DY$1)/($F4-$U1),0) -> 0
C6: Nouvelles productions 2027 | AG6: ='Plan Moyen Terme (PMT)'!D4-BAU_Liquidité_Dynamique!AG4 -> 274.5002 | AH6: =IF(AND(AG1<AH$1, AH$1<=$F4),$AG6*($F4-AH1)/($F4-$AG1),0) -> 266.8752 | AI6: =IF(AND(AH1<AI$1, AI$1<=$F4),$AG6*($F4-AI1)/($F4-$AG1),0) -> 259.25019 | AJ6: =IF(AND(AI1<AJ$1, AJ$1<=$F4),$AG6*($F4-AJ1)/($F4-$AG1),0) -> 251.62519 | AK6: =IF(AND(AJ1<AK$1, AK$1<=$F4),$AG6*($F4-AK1)/($F4-$AG1),0) -> 244.00018 | AL6: =IF(AND(AK1<AL$1, AL$1<=$F4),$AG6*($F4-AL1)/($F4-$AG1),0) -> 236.37518 | AM6: =IF(AND(AL1<AM$1, AM$1<=$F4),$AG6*($F4-AM1)/($F4-$AG1),0) -> 228.75017 | AN6: =IF(AND(AM1<AN$1, AN$1<=$F4),$AG6*($F4-AN1)/($F4-$AG1),0) -> 221.12516 | AO6: =IF(AND(AN1<AO$1, AO$1<=$F4),$AG6*($F4-AO1)/($F4-$AG1),0) -> 213.50016 | ... BQ6: =IF(AND(BP1<BQ$1, BQ$1<=$F4),$AG6*($F4-BQ1)/($F4-$AG1),0) -> 0 | BR6: =IF(BR$1<$F4-$AG1,$AG6*($F4-BR1)/($F4-$AG1),0) -> 0 | BS6: =IF(BS$1<$F4-$AG1,$AG6*($F4-BS1)/($F4-$AG1),0) -> 0 | BT6: =IF(BT$1<$F4-$AG1,$AG6*($F4-BT1)/($F4-$AG1),0) -> 0 | BU6: =IF(BU$1<$F4-$AG1,$AG6*($F4-BU1)/($F4-$AG1),0) -> 0 | BV6: =IF(BV$1<$F4-$AG1,$AG6*($F4-BV1)/($F4-$AG1),0) -> 0 | BW6: =IF(BW$1<$F4-$AG1,$AG6*($F4-BW1)/($F4-$AG1),0) -> 0 | BX6: =IF(BX$1<$F4-$AG1,$AG6*($F4-BX1)/($F4-$AG1),0) -> 0 | BY6: =IF(BY$1<$F4-$AG1,$AG6*($F4-BY1)/($F4-$AG1),0) -> 0 | ... DY6: =IF(DY$1<$F4-$AG1,$AG6*($F4-DY1)/($F4-$AG1),0) -> 0
C7: Nouvelles productions 2028 | AS7: ='Plan Moyen Terme (PMT)'!E4-BAU_Liquidité_Dynamique!AS4 -> 229.86212 | AT7: =IF(AND(AS1<AT$1, AT$1<=$F4),$AS$7*($F$4-AT1)/($F$4-$AS1),0) -> 220.28453 | AU7: =IF(AND(AT1<AU$1, AU$1<=$F4),$AS$7*($F$4-AU1)/($F$4-$AS1),0) -> 210.70694 | AV7: =IF(AND(AU1<AV$1, AV$1<=$F4),$AS$7*($F$4-AV1)/($F$4-$AS1),0) -> 201.12935 | AW7: =IF(AND(AV1<AW$1, AW$1<=$F4),$AS$7*($F$4-AW1)/($F$4-$AS1),0) -> 191.55176 | AX7: =IF(AND(AW1<AX$1, AX$1<=$F4),$AS$7*($F$4-AX1)/($F$4-$AS1),0) -> 181.97418 | AY7: =IF(AND(AX1<AY$1, AY$1<=$F4),$AS$7*($F$4-AY1)/($F$4-$AS1),0) -> 172.39659 | AZ7: =IF(AND(AY1<AZ$1, AZ$1<=$F4),$AS$7*($F$4-AZ1)/($F$4-$AS1),0) -> 162.819 | BA7: =IF(AND(AZ1<BA$1, BA$1<=$F4),$AS$7*($F$4-BA1)/($F$4-$AS1),0) -> 153.24141 | ... BQ7: =IF(AND(BP1<BQ$1, BQ$1<=$F4),$AS$7*($F$4-BQ1)/($F$4-$AS1),0) -> 0
A8: 46022 | B8: ACTIF | C8: - Compte courant BDF | D8: 0.00040572687 | E8: Linéaire | F8: 120 | G8: Ine fine | H8: 120 | I8: 1214.5371 | J8: =IF(J$1<$F8,$I8*(($F8-J$1)/$F8),0) -> 1204.416 | K8: =IF(K$1<$F8,$I8*(($F8-K$1)/$F8),0) -> 1194.2948 | L8: =IF(L$1<$F8,$I8*(($F8-L$1)/$F8),0) -> 1184.1737 | M8: =IF(M$1<$F8,$I8*(($F8-M$1)/$F8),0) -> 1174.0525 | N8: =IF(N$1<$F8,$I8*(($F8-N$1)/$F8),0) -> 1163.9314 | O8: =IF(O$1<$F8,$I8*(($F8-O$1)/$F8),0) -> 1153.8103 | P8: =IF(P$1<$F8,$I8*(($F8-P$1)/$F8),0) -> 1143.6891 | Q8: =IF(Q$1<$F8,$I8*(($F8-Q$1)/$F8),0) -> 1133.568 | ... DY8: =IF(DY$1<$F8,$I8*(($F8-DY$1)/$F8),0) -> 0
C9: Nouvelles productions 2026 | U9: ='Plan Moyen Terme (PMT)'!C5-BAU_Liquidité_Dynamique!U8 -> 175.23103 | V9: =IF(AND(U1<V$1, V$1<=$F8),$U9*($F8-V$1)/($F8-$U$1),0) -> 173.60852 | W9: =IF(AND(V1<W$1, W$1<=$F8),$U9*($F8-W$1)/($F8-$U$1),0) -> 171.98601 | X9: =IF(AND(W1<X$1, X$1<=$F8),$U9*($F8-X$1)/($F8-$U$1),0) -> 170.3635 | Y9: =IF(AND(X1<Y$1, Y$1<=$F8),$U9*($F8-Y$1)/($F8-$U$1),0) -> 168.74099 | Z9: =IF(AND(Y1<Z$1, Z$1<=$F8),$U9*($F8-Z$1)/($F8-$U$1),0) -> 167.11848 | AA9: =IF(AND(Z1<AA$1, AA$1<=$F8),$U9*($F8-AA$1)/($F8-$U$1),0) -> 165.49597 | AB9: =IF(AND(AA1<AB$1, AB$1<=$F8),$U9*($F8-AB$1)/($F8-$U$1),0) -> 163.87347 | AC9: =IF(AND(AB1<AC$1, AC$1<=$F8),$U9*($F8-AC$1)/($F8-$U$1),0) -> 162.25096 | ... DY9: =IF(AND(DX1<DY$1, DY$1<=$F8),$U9*($F8-DY$1)/($F8-$U$1),0) -> 0
C10: Nouvelles productions 2027 | AG10: ='Plan Moyen Terme (PMT)'!D5-BAU_Liquidité_Dynamique!AG8 -> 6047.3703 | AH10: =IF(AND(AG1<AH$1, AH$1<=$F8),$AG10*($F8-AH$1)/($F8-$AG$1),0) -> 5984.3769 | AI10: =IF(AND(AH1<AI$1, AI$1<=$F8),$AG10*($F8-AI$1)/($F8-$AG$1),0) -> 5921.3834 | AJ10: =IF(AND(AI1<AJ$1, AJ$1<=$F8),$AG10*($F8-AJ$1)/($F8-$AG$1),0) -> 5858.39 | AK10: =IF(AND(AJ1<AK$1, AK$1<=$F8),$AG10*($F8-AK$1)/($F8-$AG$1),0) -> 5795.3965 | AL10: =IF(AND(AK1<AL$1, AL$1<=$F8),$AG10*($F8-AL$1)/($F8-$AG$1),0) -> 5732.4031 | AM10: =IF(AND(AL1<AM$1, AM$1<=$F8),$AG10*($F8-AM$1)/($F8-$AG$1),0) -> 5669.4097 | AN10: =IF(AND(AM1<AN$1, AN$1<=$F8),$AG10*($F8-AN$1)/($F8-$AG$1),0) -> 5606.4162 | AO10: =IF(AND(AN1<AO$1, AO$1<=$F8),$AG10*($F8-AO$1)/($F8-$AG$1),0) -> 5543.4228 | ... DY10: =IF(AND(DX1<DY$1, DY$1<=$F8),$AG10*($F8-DY$1)/($F8-$AG$1),0) -> 0
C11: Nouvelles productions 2028 | AS11: ='Plan Moyen Terme (PMT)'!E5-BAU_Liquidité_Dynamique!AS8 -> 4440.824 | AT11: =IF(AND(AS1<AT$1, AT$1<=$F8),$AS11*($F8-AT$1)/($F8-$AS$1),0) -> 4387.9571 | AU11: =IF(AND(AT1<AU$1, AU$1<=$F8),$AS11*($F8-AU$1)/($F8-$AS$1),0) -> 4335.0901 | AV11: =IF(AND(AU1<AV$1, AV$1<=$F8),$AS11*($F8-AV$1)/($F8-$AS$1),0) -> 4282.2232 | AW11: =IF(AND(AV1<AW$1, AW$1<=$F8),$AS11*($F8-AW$1)/($F8-$AS$1),0) -> 4229.3562 | AX11: =IF(AND(AW1<AX$1, AX$1<=$F8),$AS11*($F8-AX$1)/($F8-$AS$1),0) -> 4176.4893 | AY11: =IF(AND(AX1<AY$1, AY$1<=$F8),$AS11*($F8-AY$1)/($F8-$AS$1),0) -> 4123.6223 | AZ11: =IF(AND(AY1<AZ$1, AZ$1<=$F8),$AS11*($F8-AZ$1)/($F8-$AS$1),0) -> 4070.7553 | BA11: =IF(AND(AZ1<BA$1, BA$1<=$F8),$AS11*($F8-BA$1)/($F8-$AS$1),0) -> 4017.8884 | ... DY11: =IF(AND(DX1<DY$1, DY$1<=$F8),$AS11*($F8-DY$1)/($F8-$AS$1),0) -> 0
A12: 46022 | B12: ACTIF | C12: CREANCES SUR LES ETS DE CREDIT | I12: =I13+I17 -> 28006.945 | J12: =SUM(J13:J17) -> 24825.899 | K12: =SUM(K13:K17) -> 21644.854 | L12: =SUM(L13:L17) -> 18463.808 | M12: =SUM(M13:M17) -> 15282.762 | N12: =SUM(N13:N17) -> 12101.717 | O12: =SUM(O13:O17) -> 8920.671 | P12: =SUM(P13:P17) -> 8920.671 | Q12: =SUM(Q13:Q17) -> 8920.671 | ... DY12: =SUM(DY13:DY17) -> 0
A13: 46022 | B13: ACTIF | C13: - A vue | D13: 0 | E13: Linéaire | F13: 6 | G13: Linéaire | H13: 6 | I13: 19086.274 | J13: =IF(J$1<$F13,$I13*(($F13-J$1)/$F13),0) -> 15905.228 | K13: =IF(K$1<$F13,$I13*(($F13-K$1)/$F13),0) -> 12724.183 | L13: =IF(L$1<$F13,$I13*(($F13-L$1)/$F13),0) -> 9543.137 | M13: =IF(M$1<$F13,$I13*(($F13-M$1)/$F13),0) -> 6362.0913 | N13: =IF(N$1<$F13,$I13*(($F13-N$1)/$F13),0) -> 3181.0457 | O13: =IF(O$1<$F13,$I13*(($F13-O$1)/$F13),0) -> 0 | P13: =IF(P$1<$F13,$I13*(($F13-P$1)/$F13),0) -> 0 | Q13: =IF(Q$1<$F13,$I13*(($F13-Q$1)/$F13),0) -> 0 | ... DY13: =IF(DY$1<$F13,$I13*(($F13-DY$1)/$F13),0) -> 0
C14: Nouvelles productions 2026=0
C15: Nouvelles productions 2027=0
C16: Nouvelles productions 2028=0
A17: 46022 | B17: ACTIF | C17: - A terme | D17: 0.02489751 | E17: In fine | F17: 12 | G17: In fine | H17: 12 | I17: 8920.671 | J17: =IF(J$1<$F17,$I17,0) -> 8920.671 | K17: =IF(K$1<$F17,$I17,0) -> 8920.671 | L17: =IF(L$1<$F17,$I17,0) -> 8920.671 | M17: =IF(M$1<$F17,$I17,0) -> 8920.671 | N17: =IF(N$1<$F17,$I17,0) -> 8920.671 | O17: =IF(O$1<$F17,$I17,0) -> 8920.671 | P17: =IF(P$1<$F17,$I17,0) -> 8920.671 | Q17: =IF(Q$1<$F17,$I17,0) -> 8920.671 | ... DY17: =IF(DY$1<$F17,$I17,0) -> 0
C18: Nouvelles productions 2026=0
C19: Nouvelles productions 2027=0 | J19: =PMT($D22/12,$F22,$I22) -> -6.7325943 | K19: =I22*D22/12 -> 1.4456894 | AH19: =AH17 -> 0 | AI19: =AG23*D22/12 -> 17.499894
C20: Nouvelles productions 2028=0
A21: 46022 | B21: ACTIF | C21: CREANCES SUR LA CLIENTELE | I21: =I22+I26+I30 -> 125650.32 | J21: =SUM(J22:J30) -> 45066.509 | K21: =SUM(K22:K30) -> 40146.149 | L21: =SUM(L22:L30) -> 35212.566 | M21: =SUM(M22:M30) -> 30265.727 | N21: =SUM(N22:N30) -> 25305.594 | O21: =SUM(O22:O30) -> 20332.132 | P21: =SUM(P22:P30) -> 15345.305 | Q21: =SUM(Q22:Q30) -> 10345.078 | ... DY21: =SUM(DY22:DY30) -> 0
A22: 46022 | B22: ACTIF | C22: - Créances commerciales | D22: 0.048443032 | E22: Constant | F22: 60 | G22: Constant | H22: 60 | I22: 358.117 | J22: =IF(J$1<$F22,(I22*(1+($D22/12)))-(-PMT($D22/12,$F22,$I22)),0) -> 352.8301 | K22: =IF(K$1<$F22,(J22*(1+($D22/12)))-(-PMT($D22/12,$F22,$I22)),0) -> 347.52185 | L22: =IF(L$1<$F22,(K22*(1+($D22/12)))-(-PMT($D22/12,$F22,$I22)),0) -> 342.19217 | M22: =IF(M$1<$F22,(L22*(1+($D22/12)))-(-PMT($D22/12,$F22,$I22)),0) -> 336.84098 | N22: =IF(N$1<$F22,(M22*(1+($D22/12)))-(-PMT($D22/12,$F22,$I22)),0) -> 331.46818 | O22: =IF(O$1<$F22,(N22*(1+($D22/12)))-(-PMT($D22/12,$F22,$I22)),0) -> 326.0737 | P22: =IF(P$1<$F22,(O22*(1+($D22/12)))-(-PMT($D22/12,$F22,$I22)),0) -> 320.65744 | Q22: =IF(Q$1<$F22,(P22*(1+($D22/12)))-(-PMT($D22/12,$F22,$I22)),0) -> 315.21931 | ... DY22: =IF(DY$1<$F22,(DX22*(1+($D22/12)))-(-PMT($D22/12,$F22,$I22)),0) -> 0
C23: Nouvelles productions 2026 | U23: ='Plan Moyen Terme (PMT)'!C10-BAU_Liquidité_Dynamique!U22 -> 5645.7536 | V23: =IF(AND(U1<V$1, V$1<=$F$22),(U23*(1+($D$22/12)))-(-PMT($D$22/12,$F$22-$U1,$U$23)),0) -> 5538.9252 | W23: =IF(AND(V1<W$1, W$1<=$F$22),(V23*(1+($D$22/12)))-(-PMT($D$22/12,$F$22-$U1,$U$23)),0) -> 5431.6655 | X23: =IF(AND(W1<X$1, X$1<=$F$22),(W23*(1+($D$22/12)))-(-PMT($D$22/12,$F$22-$U1,$U$23)),0) -> 5323.9727 | Y23: =IF(AND(X1<Y$1, Y$1<=$F$22),(X23*(1+($D$22/12)))-(-PMT($D$22/12,$F$22-$U1,$U$23)),0) -> 5215.8453 | Z23: =IF(AND(Y1<Z$1, Z$1<=$F$22),(Y23*(1+($D$22/12)))-(-PMT($D$22/12,$F$22-$U1,$U$23)),0) -> 5107.2813 | AA23: =IF(AND(Z1<AA$1, AA$1<=$F$22),(Z23*(1+($D$22/12)))-(-PMT($D$22/12,$F$22-$U1,$U$23)),0) -> 4998.2791 | AB23: =IF(AND(AA1<AB$1, AB$1<=$F$22),(AA23*(1+($D$22/12)))-(-PMT($D$22/12,$F$22-$U1,$U$23)),0) -> 4888.8369 | AC23: =IF(AND(AB1<AC$1, AC$1<=$F$22),(AB23*(1+($D$22/12)))-(-PMT($D$22/12,$F$22-$U1,$U$23)),0) -> 4778.9528 | ... BQ23: =IF(AND(BP1<BQ$1, BQ$1<=$F$22),(BP23*(1+($D$22/12)))-(-PMT($D$22/12,$F$22-$U1,$U$23)),0) -> -5.1727511e-12
C24: Nouvelles productions 2027 | AG24: ='Plan Moyen Terme (PMT)'!D10-BAU_Liquidité_Dynamique!AG22 -> 3744.8375 | AH24: =IF(AND(AG1<AH$1, AH$1<=$F22),(AG24*(1+$D22/12))+(PMT($D22/12,$F22-$AG1,$AG24)),0) -> 3647.9805 | AI24: =IF(AND(AH1<AI$1, AI$1<=$F22),(AH24*(1+$D22/12))+(PMT($D22/12,$F22-$AG1,$AG24)),0) -> 3550.7326 | AJ24: =IF(AND(AI1<AJ$1, AJ$1<=$F22),(AI24*(1+$D22/12))+(PMT($D22/12,$F22-$AG1,$AG24)),0) -> 3453.0921 | AK24: =IF(AND(AJ1<AK$1, AK$1<=$F22),(AJ24*(1+$D22/12))+(PMT($D22/12,$F22-$AG1,$AG24)),0) -> 3355.0574 | AL24: =IF(AND(AK1<AL$1, AL$1<=$F22),(AK24*(1+$D22/12))+(PMT($D22/12,$F22-$AG1,$AG24)),0) -> 3256.6269 | AM24: =IF(AND(AL1<AM$1, AM$1<=$F22),(AL24*(1+$D22/12))+(PMT($D22/12,$F22-$AG1,$AG24)),0) -> 3157.7991 | AN24: =IF(AND(AM1<AN$1, AN$1<=$F22),(AM24*(1+$D22/12))+(PMT($D22/12,$F22-$AG1,$AG24)),0) -> 3058.5724 | AO24: =IF(AND(AN1<AO$1, AO$1<=$F22),(AN24*(1+$D22/12))+(PMT($D22/12,$F22-$AG1,$AG24)),0) -> 2958.945 | ... BQ24: =IF(AND(BP1<BQ$1, BQ$1<=$F22),(BP24*(1+$D22/12))+(PMT($D22/12,$F22-$AG1,$AG24)),0) -> -1.7337243e-12
